Workbook

Sheet CEI_COMPLETA
A1: Nome da Origem | B1: Códigos | C1: Transações e saldos | D1: USOS | E1: RECURSOS
A2: 2000 | B2: P.7 | C2: Importação de bens e serviços
A3: 2000 | B3: P.6 | C3: Exportação de bens e serviços
A4: 2000 | B4: P.1 | C4: Produção | E4: 388773
A5: 2000 | B5: P.2 | C5: Consumo intermediário | D5: 97391
A6: 2000 | B6: D.21-D.31 | C6: Impostos, líquidos de subsídios, sobre produtos
A7: 2000 | B7: B.1 | C7: Valor adicionado bruto/Produto interno bruto (1) | D7: 291382 | E7: 291382
A8: 2000 | B8: B.11 | C8: Saldo externo de bens e serviços
A9: 2000 | B9: D.1 | C9: Remuneração dos empregados | D9: 28608 | E9: 470094
A10: 2000 | B10: D.11 | C10: Ordenados e salários | D10: 24362 | E10: 380925
A11: 2000 | B11: D.12 | C11: Contribuições sociais dos empregadores | D11: 4246 | E11: 89169
A12: 2000 | B12: D.121 | C12: Contribuições sociais efetivas | D12: 4246 | E12: 67435
A13: 2000 | B13: D.122 | C13: Contribuições sociais imputadas | E13: 21734
A14: 2000 | B14: D.2-D.3 | C14: Impostos, líquidos de subsídios, sobre a produção e a importação | D14: -1189
A15: 2000 | B15: D.29-D.39 | C15: Outros impostos, líquidos de subsídios, sobre a produção | D15: -1189
A16: 2000 | B16: B.2 | C16: Excedente operacional bruto | D16: 115598 | E16: 115598
A17: 2000 | B17: B.3 | C17: Rendimento misto bruto (rendimento de autônomos) | D17: 148365 | E17: 148365
A18: 2000 | B18: D.4 | C18: Rendas de propriedade | D18: 17092 | E18: 148856
A19: 2000 | B19: D.41 | C19: Juros | D19: 17027 | E19: 67149
A20: 2000 | B20: D.42 | C20: Dividendos e retiradas | E20: 70376
A21: 2000 | B21: D.43-D.44 | C21: Desembolsos por rendas de investimentos / Lucros reinvestidos de investimento direto estrangeiro | E21: 11331
A22: 2000 | B22: D.45 | C22: Renda de recursos naturais | D22: 65
A23: 2000 | B23: B.5 | C23: Saldo das rendas primárias brutas/Renda nacional bruta (2) | D23: 865821 | E23: 865821
A24: 2000 | B24: D.5 | C24: Impostos correntes sobre a renda, patrimônio, etc. | D24: 38568
A25: 2000 | B25: D.61 | C25: Contribuições sociais | D25: 129632
A26: 2000 | B26: D.611 | C26: Contribuições sociais efetivas dos empregadores | D26: 67435
A27: 2000 | B27: D.612 | C27: Contribuições sociais imputadas dos empregadores | D27: 21734
A28: 2000 | B28: D.613 | C28: Contribuições sociais efetivas das famílias/empregados | D28: 40463
A29: 2000 | B29: D.62 | C29: Benefícios sociais, exceto transferências sociais em espécie | E29: 160298
A30: 2000 | B30: D.621 | C30: Benefícios de seguridade social em numerário | E30: 70874
A31: 2000 | B31: D.622 | C31: Outros benefícios de seguro social | E31: 86655
A32: 2000 | B32: D.623 | C32: Benefícios de assistência social em numerário | E32: 2769
A33: 2000 | B33: D.7 | C33: Outras transferências correntes | D33: 15190 | E33: 6592
A34: 2000 | B34: D.71 | C34: Prêmios líquidos de seguros não-vida | D34: 2584
A35: 2000 | B35: D.72 | C35: Indenizações de seguros não-vida | E35: 2815
A36: 2000 | B36: D.73 | C36: Transferências correntes entre administrações públicas
A37: 2000 | B37: D.74 | C37: Cooperação Internacional
A38: 2000 | B38: D.75 | C38: Transferências correntes diversas | D38: 12606 | E38: 3777
A39: 2000 | B39: B.6 | C39: Renda disponível bruta | D39: 849321 | E39: 849321
A40: 2000 | B40: D.63 | C40: Transferências sociais em espécie | E40: 107799
...

Sheet Ajustes
A1: ORIGINAL | B1: Renda nacional disponível bruta | C1: Despesa de consumo final | D1: Formação Bruta de Capital Fixo | E1: Investimento Residencial | F1: Juros pessoais | G1: Transferências | H1: Poupança bruta | I1: Renda nacional disponível bruta | J1: Despesa de consumo final | K1: Formação Bruta de Capital Fixo | L1: Investimento Residencial | M1: Juros pessoais | N1: Transferências | O1: Poupança bruta | P1: FONTE | Q1: LINHA | S1: RECURSO/USO | T1: 2000 | U1: 2001 | V1: 2002 | W1: 2003 | X1: 2004 | Y1: 2005 | Z1: 2006 | AA1: 2007 | AB1: 2008 | AC1: 2009 | AD1: 2010 | AE1: 2011 | AF1: 2012 | AG1: 2013 | AH1: 2014 | AI1: 2015 | AJ1: 2016 | AK1: 2017 | AL1: 2018 | AM1: 2019 | AN1: 2020 | AO1: 2021
A2: Renda nacional disponível bruta | P2: CEI | Q2: B.6 | R2: B.6 | S2: R | T2: =_xlfn.LET( _xlpm.intervaloSoma, IF($S2="R", 'CEI_COMPLETA'!$E:$E, 'CEI_COMPLETA'!$D:$D), SUMIFS(_xlpm.intervaloSoma, 'CEI_COMPLETA'!$A:$A, Ajustes!T$1, 'CEI_COMPLETA'!$B:$B, Ajustes!$Q2) ) -> 849321 | U2: =_xlfn.LET( _xlpm.intervaloSoma, IF($S2="R", 'CEI_COMPLETA'!$E:$E, 'CEI_COMPLETA'!$D:$D), SUMIFS(_xlpm.intervaloSoma, 'CEI_COMPLETA'!$A:$A, Ajustes!U$1, 'CEI_COMPLETA'!$B:$B, Ajustes!$Q2) ) -> 921972 | V2: =_xlfn.LET( _xlpm.intervaloSoma, IF($S2="R", 'CEI_COMPLETA'!$E:$E, 'CEI_COMPLETA'!$D:$D), SUMIFS(_xlpm.intervaloSoma, 'CEI_COMPLETA'!$A:$A, Ajustes!V$1, 'CEI_COMPLETA'!$B:$B, Ajustes!$Q2) ) -> 1011475 | W2: =_xlfn.LET( _xlpm.intervaloSoma, IF($S2="R", 'CEI_COMPLETA'!$E:$E, 'CEI_COMPLETA'!$D:$D), SUMIFS(_xlpm.intervaloSoma, 'CEI_COMPLETA'!$A:$A, Ajustes!W$1, 'CEI_COMPLETA'!$B:$B, Ajustes!$Q2) ) -> 1154362 | X2: =_xlfn.LET( _xlpm.intervaloSoma, IF($S2="R", 'CEI_COMPLETA'!$E:$E, 'CEI_COMPLETA'!$D:$D), SUMIFS(_xlpm.intervaloSoma, 'CEI_COMPLETA'!$A:$A, Ajustes!X$1, 'CEI_COMPLETA'!$B:$B, Ajustes!$Q2) ) -> 1276698 | Y2: =_xlfn.LET( _xlpm.intervaloSoma, IF($S2="R", 'CEI_COMPLETA'!$E:$E, 'CEI_COMPLETA'!$D:$D), SUMIFS(_xlpm.intervaloSoma, 'CEI_COMPLETA'!$A:$A, Ajustes!Y$1, 'CEI_COMPLETA'!$B:$B, Ajustes!$Q2) ) -> 1406510 | Z2: =_xlfn.LET( _xlpm.intervaloSoma, IF($S2="R", 'CEI_COMPLETA'!$E:$E, 'CEI_COMPLETA'!$D:$D), SUMIFS(_xlpm.intervaloSoma, 'CEI_COMPLETA'!$A:$A, Ajustes!Z$1, 'CEI_COMPLETA'!$B:$B, Ajustes!$Q2) ) -> 1546184 | AA2: =_xlfn.LET( _xlpm.intervaloSoma, IF($S2="R", 'CEI_COMPLETA'!$E:$E, 'CEI_COMPLETA'!$D:$D), SUMIFS(_xlpm.intervaloSoma, 'CEI_COMPLETA'!$A:$A, Ajustes!AA$1, 'CEI_COMPLETA'!$B:$B, Ajustes!$Q2) ) -> 1737958 | ... AC2: =_xlfn.LET( _xlpm.intervaloSoma, IF($S2="R", 'CEI_COMPLETA'!$E:$E, 'CEI_COMPLETA'!$D:$D), SUMIFS(_xlpm.intervaloSoma, 'CEI_COMPLETA'!$A:$A, Ajustes!AC$1, 'CEI_COMPLETA'!$B:$B, Ajustes!$Q2) ) -> 2202388 | AD2: =_xlfn.LET( _xlpm.intervaloSoma, IF($S2="R", 'CEI_COMPLETA'!$E:$E, 'CEI_COMPLETA'!$D:$D), SUMIFS(_xlpm.intervaloSoma, 'CEI_COMPLETA'!$A:$A, Ajustes!AD$1, 'CEI_COMPLETA'!$B:$B, Ajustes!$R2) ) -> 2492302 | AE2: =_xlfn.LET( _xlpm.intervaloSoma, IF($S2="R", 'CEI_COMPLETA'!$E:$E, 'CEI_COMPLETA'!$D:$D), SUMIFS(_xlpm.intervaloSoma, 'CEI_COMPLETA'!$A:$A, Ajustes!AE$1, 'CEI_COMPLETA'!$B:$B, Ajustes!$R2) ) -> 2828939 | AF2: =_xlfn.LET( _xlpm.intervaloSoma, IF($S2="R", 'CEI_COMPLETA'!$E:$E, 'CEI_COMPLETA'!$D:$D), SUMIFS(_xlpm.intervaloSoma, 'CEI_COMPLETA'!$A:$A, Ajustes!AF$1, 'CEI_COMPLETA'!$B:$B, Ajustes!$R2) ) -> 3161213 | AG2: =_xlfn.LET( _xlpm.intervaloSoma, IF($S2="R", 'CEI_COMPLETA'!$E:$E, 'CEI_COMPLETA'!$D:$D), SUMIFS(_xlpm.intervaloSoma, 'CEI_COMPLETA'!$A:$A, Ajustes!AG$1, 'CEI_COMPLETA'!$B:$B, Ajustes!$R2) ) -> 3550416 | AH2: =_xlfn.LET( _xlpm.intervaloSoma, IF($S2="R", 'CEI_COMPLETA'!$E:$E, 'CEI_COMPLETA'!$D:$D), SUMIFS(_xlpm.intervaloSoma, 'CEI_COMPLETA'!$A:$A, Ajustes!AH$1, 'CEI_COMPLETA'!$B:$B, Ajustes!$R2) ) -> 3898396 | AI2: =_xlfn.LET( _xlpm.intervaloSoma, IF($S2="R", 'CEI_COMPLETA'!$E:$E, 'CEI_COMPLETA'!$D:$D), SUMIFS(_xlpm.intervaloSoma, 'CEI_COMPLETA'!$A:$A, Ajustes!AI$1, 'CEI_COMPLETA'!$B:$B, Ajustes!$R2) ) -> 4148220 | AJ2: =_xlfn.LET( _xlpm.intervaloSoma, IF($S2="R", 'CEI_COMPLETA'!$E:$E, 'CEI_COMPLETA'!$D:$D), SUMIFS(_xlpm.intervaloSoma, 'CEI_COMPLETA'!$A:$A, Ajustes!AJ$1, 'CEI_COMPLETA'!$B:$B, Ajustes!$R2) ) -> 4404397 | AK2: =_xlfn.LET( _xlpm.intervaloSoma, IF($S2="R", 'CEI_COMPLETA'!$E:$E, 'CEI_COMPLETA'!$D:$D), SUMIFS(_xlpm.intervaloSoma, 'CEI_COMPLETA'!$A:$A, Ajustes!AK$1, 'CEI_COMPLETA'!$B:$B, Ajustes!$R2) ) -> 4704231 | ... AO2: =_xlfn.LET( _xlpm.intervaloSoma, IF($S2="R", 'CEI_COMPLETA'!$E:$E, 'CEI_COMPLETA'!$D:$D), SUMIFS(_xlpm.intervaloSoma, 'CEI_COMPLETA'!$A:$A, Ajustes!AO$1, 'CEI_COMPLETA'!$B:$B, Ajustes!$R2) ) -> 5937056
A3: Despesa de consumo final | P3: CEI | Q3: P.3 | R3: P.3 | S3: U | T3: =_xlfn.LET( _xlpm.intervaloSoma, IF($S3="R", 'CEI_COMPLETA'!$E:$E, 'CEI_COMPLETA'!$D:$D), SUMIFS(_xlpm.intervaloSoma, 'CEI_COMPLETA'!$A:$A, Ajustes!T$1, 'CEI_COMPLETA'!$B:$B, Ajustes!$Q3) ) -> 754333 | U3: =_xlfn.LET( _xlpm.intervaloSoma, IF($S3="R", 'CEI_COMPLETA'!$E:$E, 'CEI_COMPLETA'!$D:$D), SUMIFS(_xlpm.intervaloSoma, 'CEI_COMPLETA'!$A:$A, Ajustes!U$1, 'CEI_COMPLETA'!$B:$B, Ajustes!$Q3) ) -> 822656 | V3: =_xlfn.LET( _xlpm.intervaloSoma, IF($S3="R", 'CEI_COMPLETA'!$E:$E, 'CEI_COMPLETA'!$D:$D), SUMIFS(_xlpm.intervaloSoma, 'CEI_COMPLETA'!$A:$A, Ajustes!V$1, 'CEI_COMPLETA'!$B:$B, Ajustes!$Q3) ) -> 895614 | W3: =_xlfn.LET( _xlpm.intervaloSoma, IF($S3="R", 'CEI_COMPLETA'!$E:$E, 'CEI_COMPLETA'!$D:$D), SUMIFS(_xlpm.intervaloSoma, 'CEI_COMPLETA'!$A:$A, Ajustes!W$1, 'CEI_COMPLETA'!$B:$B, Ajustes!$Q3) ) -> 1035030 | X3: =_xlfn.LET( _xlpm.intervaloSoma, IF($S3="R", 'CEI_COMPLETA'!$E:$E, 'CEI_COMPLETA'!$D:$D), SUMIFS(_xlpm.intervaloSoma, 'CEI_COMPLETA'!$A:$A, Ajustes!X$1, 'CEI_COMPLETA'!$B:$B, Ajustes!$Q3) ) -> 1147362 | Y3: =_xlfn.LET( _xlpm.intervaloSoma, IF($S3="R", 'CEI_COMPLETA'!$E:$E, 'CEI_COMPLETA'!$D:$D), SUMIFS(_xlpm.intervaloSoma, 'CEI_COMPLETA'!$A:$A, Ajustes!Y$1, 'CEI_COMPLETA'!$B:$B, Ajustes!$Q3) ) -> 1277027 | Z3: =_xlfn.LET( _xlpm.intervaloSoma, IF($S3="R", 'CEI_COMPLETA'!$E:$E, 'CEI_COMPLETA'!$D:$D), SUMIFS(_xlpm.intervaloSoma, 'CEI_COMPLETA'!$A:$A, Ajustes!Z$1, 'CEI_COMPLETA'!$B:$B, Ajustes!$Q3) ) -> 1411686 | AA3: =_xlfn.LET( _xlpm.intervaloSoma, IF($S3="R", 'CEI_COMPLETA'!$E:$E, 'CEI_COMPLETA'!$D:$D), SUMIFS(_xlpm.intervaloSoma, 'CEI_COMPLETA'!$A:$A, Ajustes!AA$1, 'CEI_COMPLETA'!$B:$B, Ajustes!$Q3) ) -> 1585632 | ... AC3: =_xlfn.LET( _xlpm.intervaloSoma, IF($S3="R", 'CEI_COMPLETA'!$E:$E, 'CEI_COMPLETA'!$D:$D), SUMIFS(_xlpm.intervaloSoma, 'CEI_COMPLETA'!$A:$A, Ajustes!AC$1, 'CEI_COMPLETA'!$B:$B, Ajustes!$Q3) ) -> 2011763 | AD3: =_xlfn.LET( _xlpm.intervaloSoma, IF($S3="R", 'CEI_COMPLETA'!$E:$E, 'CEI_COMPLETA'!$D:$D), SUMIFS(_xlpm.intervaloSoma, 'CEI_COMPLETA'!$A:$A, Ajustes!AD$1, 'CEI_COMPLETA'!$B:$B, Ajustes!$R3) ) -> 2278735 | AE3: =_xlfn.LET( _xlpm.intervaloSoma, IF($S3="R", 'CEI_COMPLETA'!$E:$E, 'CEI_COMPLETA'!$D:$D), SUMIFS(_xlpm.intervaloSoma, 'CEI_COMPLETA'!$A:$A, Ajustes!AE$1, 'CEI_COMPLETA'!$B:$B, Ajustes!$R3) ) -> 2573419 | AF3: =_xlfn.LET( _xlpm.intervaloSoma, IF($S3="R", 'CEI_COMPLETA'!$E:$E, 'CEI_COMPLETA'!$D:$D), SUMIFS(_xlpm.intervaloSoma, 'CEI_COMPLETA'!$A:$A, Ajustes!AF$1, 'CEI_COMPLETA'!$B:$B, Ajustes!$R3) ) -> 2883929 | AG3: =_xlfn.LET( _xlpm.intervaloSoma, IF($S3="R", 'CEI_COMPLETA'!$E:$E, 'CEI_COMPLETA'!$D:$D), SUMIFS(_xlpm.intervaloSoma, 'CEI_COMPLETA'!$A:$A, Ajustes!AG$1, 'CEI_COMPLETA'!$B:$B, Ajustes!$R3) ) -> 3213817 | AH3: =_xlfn.LET( _xlpm.intervaloSoma, IF($S3="R", 'CEI_COMPLETA'!$E:$E, 'CEI_COMPLETA'!$D:$D), SUMIFS(_xlpm.intervaloSoma, 'CEI_COMPLETA'!$A:$A, Ajustes!AH$1, 'CEI_COMPLETA'!$B:$B, Ajustes!$R3) ) -> 3555352 | AI3: =_xlfn.LET( _xlpm.intervaloSoma, IF($S3="R", 'CEI_COMPLETA'!$E:$E, 'CEI_COMPLETA'!$D:$D), SUMIFS(_xlpm.intervaloSoma, 'CEI_COMPLETA'!$A:$A, Ajustes!AI$1, 'CEI_COMPLETA'!$B:$B, Ajustes!$R3) ) -> 3747870 | AJ3: =_xlfn.LET( _xlpm.intervaloSoma, IF($S3="R", 'CEI_COMPLETA'!$E:$E, 'CEI_COMPLETA'!$D:$D), SUMIFS(_xlpm.intervaloSoma, 'CEI_COMPLETA'!$A:$A, Ajustes!AJ$1, 'CEI_COMPLETA'!$B:$B, Ajustes!$R3) ) -> 3939208 | AK3: =_xlfn.LET( _xlpm.intervaloSoma, IF($S3="R", 'CEI_COMPLETA'!$E:$E, 'CEI_COMPLETA'!$D:$D), SUMIFS(_xlpm.intervaloSoma, 'CEI_COMPLETA'!$A:$A, Ajustes!AK$1, 'CEI_COMPLETA'!$B:$B, Ajustes!$R3) ) -> 4156152 | ... AO3: =_xlfn.LET( _xlpm.intervaloSoma, IF($S3="R", 'CEI_COMPLETA'!$E:$E, 'CEI_COMPLETA'!$D:$D), SUMIFS(_xlpm.intervaloSoma, 'CEI_COMPLETA'!$A:$A, Ajustes!AO$1, 'CEI_COMPLETA'!$B:$B, Ajustes!$R3) ) -> 5415523
A4: Formação Bruta de Capital Fixo | P4: CEI | Q4: P.51 | R4: P.51 | S4: U | T4: =_xlfn.LET( _xlpm.intervaloSoma, IF($S4="R", 'CEI_COMPLETA'!$E:$E, 'CEI_COMPLETA'!$D:$D), SUMIFS(_xlpm.intervaloSoma, 'CEI_COMPLETA'!$A:$A, Ajustes!T$1, 'CEI_COMPLETA'!$B:$B, Ajustes!$Q4) ) -> 81409 | U4: =_xlfn.LET( _xlpm.intervaloSoma, IF($S4="R", 'CEI_COMPLETA'!$E:$E, 'CEI_COMPLETA'!$D:$D), SUMIFS(_xlpm.intervaloSoma, 'CEI_COMPLETA'!$A:$A, Ajustes!U$1, 'CEI_COMPLETA'!$B:$B, Ajustes!$Q4) ) -> 81411 | V4: =_xlfn.LET( _xlpm.intervaloSoma, IF($S4="R", 'CEI_COMPLETA'!$E:$E, 'CEI_COMPLETA'!$D:$D), SUMIFS(_xlpm.intervaloSoma, 'CEI_COMPLETA'!$A:$A, Ajustes!V$1, 'CEI_COMPLETA'!$B:$B, Ajustes!$Q4) ) -> 94472 | W4: =_xlfn.LET( _xlpm.intervaloSoma, IF($S4="R", 'CEI_COMPLETA'!$E:$E, 'CEI_COMPLETA'!$D:$D), SUMIFS(_xlpm.intervaloSoma, 'CEI_COMPLETA'!$A:$A, Ajustes!W$1, 'CEI_COMPLETA'!$B:$B, Ajustes!$Q4) ) -> 102164 | X4: =_xlfn.LET( _xlpm.intervaloSoma, IF($S4="R", 'CEI_COMPLETA'!$E:$E, 'CEI_COMPLETA'!$D:$D), SUMIFS(_xlpm.intervaloSoma, 'CEI_COMPLETA'!$A:$A, Ajustes!X$1, 'CEI_COMPLETA'!$B:$B, Ajustes!$Q4) ) -> 113120 | Y4: =_xlfn.LET( _xlpm.intervaloSoma, IF($S4="R", 'CEI_COMPLETA'!$E:$E, 'CEI_COMPLETA'!$D:$D), SUMIFS(_xlpm.intervaloSoma, 'CEI_COMPLETA'!$A:$A, Ajustes!Y$1, 'CEI_COMPLETA'!$B:$B, Ajustes!$Q4) ) -> 116178 | Z4: =_xlfn.LET( _xlpm.intervaloSoma, IF($S4="R", 'CEI_COMPLETA'!$E:$E, 'CEI_COMPLETA'!$D:$D), SUMIFS(_xlpm.intervaloSoma, 'CEI_COMPLETA'!$A:$A, Ajustes!Z$1, 'CEI_COMPLETA'!$B:$B, Ajustes!$Q4) ) -> 125113 | AA4: =_xlfn.LET( _xlpm.intervaloSoma, IF($S4="R", 'CEI_COMPLETA'!$E:$E, 'CEI_COMPLETA'!$D:$D), SUMIFS(_xlpm.intervaloSoma, 'CEI_COMPLETA'!$A:$A, Ajustes!AA$1, 'CEI_COMPLETA'!$B:$B, Ajustes!$Q4) ) -> 140587 | ... AC4: =_xlfn.LET( _xlpm.intervaloSoma, IF($S4="R", 'CEI_COMPLETA'!$E:$E, 'CEI_COMPLETA'!$D:$D), SUMIFS(_xlpm.intervaloSoma, 'CEI_COMPLETA'!$A:$A, Ajustes!AC$1, 'CEI_COMPLETA'!$B:$B, Ajustes!$Q4) ) -> 188950 | AD4: =_xlfn.LET( _xlpm.intervaloSoma, IF($S4="R", 'CEI_COMPLETA'!$E:$E, 'CEI_COMPLETA'!$D:$D), SUMIFS(_xlpm.intervaloSoma, 'CEI_COMPLETA'!$A:$A, Ajustes!AD$1, 'CEI_COMPLETA'!$B:$B, Ajustes!$R4) ) -> 232612 | AE4: =_xlfn.LET( _xlpm.intervaloSoma, IF($S4="R", 'CEI_COMPLETA'!$E:$E, 'CEI_COMPLETA'!$D:$D), SUMIFS(_xlpm.intervaloSoma, 'CEI_COMPLETA'!$A:$A, Ajustes!AE$1, 'CEI_COMPLETA'!$B:$B, Ajustes!$R4) ) -> 266481 | AF4: =_xlfn.LET( _xlpm.intervaloSoma, IF($S4="R", 'CEI_COMPLETA'!$E:$E, 'CEI_COMPLETA'!$D:$D), SUMIFS(_xlpm.intervaloSoma, 'CEI_COMPLETA'!$A:$A, Ajustes!AF$1, 'CEI_COMPLETA'!$B:$B, Ajustes!$R4) ) -> 316948 | AG4: =_xlfn.LET( _xlpm.intervaloSoma, IF($S4="R", 'CEI_COMPLETA'!$E:$E, 'CEI_COMPLETA'!$D:$D), SUMIFS(_xlpm.intervaloSoma, 'CEI_COMPLETA'!$A:$A, Ajustes!AG$1, 'CEI_COMPLETA'!$B:$B, Ajustes!$R4) ) -> 358359 | AH4: =_xlfn.LET( _xlpm.intervaloSoma, IF($S4="R", 'CEI_COMPLETA'!$E:$E, 'CEI_COMPLETA'!$D:$D), SUMIFS(_xlpm.intervaloSoma, 'CEI_COMPLETA'!$A:$A, Ajustes!AH$1, 'CEI_COMPLETA'!$B:$B, Ajustes!$R4) ) -> 371432 | AI4: =_xlfn.LET( _xlpm.intervaloSoma, IF($S4="R", 'CEI_COMPLETA'!$E:$E, 'CEI_COMPLETA'!$D:$D), SUMIFS(_xlpm.intervaloSoma, 'CEI_COMPLETA'!$A:$A, Ajustes!AI$1, 'CEI_COMPLETA'!$B:$B, Ajustes!$R4) ) -> 372116 | AJ4: =_xlfn.LET( _xlpm.intervaloSoma, IF($S4="R", 'CEI_COMPLETA'!$E:$E, 'CEI_COMPLETA'!$D:$D), SUMIFS(_xlpm.intervaloSoma, 'CEI_COMPLETA'!$A:$A, Ajustes!AJ$1, 'CEI_COMPLETA'!$B:$B, Ajustes!$R4) ) -> 361645 | AK4: =_xlfn.LET( _xlpm.intervaloSoma, IF($S4="R", 'CEI_COMPLETA'!$E:$E, 'CEI_COMPLETA'!$D:$D), SUMIFS(_xlpm.intervaloSoma, 'CEI_COMPLETA'!$A:$A, Ajustes!AK$1, 'CEI_COMPLETA'!$B:$B, Ajustes!$R4) ) -> 355517 | ... AO4: =_xlfn.LET( _xlpm.intervaloSoma, IF($S4="R", 'CEI_COMPLETA'!$E:$E, 'CEI_COMPLETA'!$D:$D), SUMIFS(_xlpm.intervaloSoma, 'CEI_COMPLETA'!$A:$A, Ajustes!AO$1, 'CEI_COMPLETA'!$B:$B, Ajustes!$R4) ) -> 499699
A5: Investimento Residencial | P5: NÃO HÁ
A6: Juros pessoais | P6: NÃO HÁ
A7: Transferências
A8: Poupança bruta | P8: CEI | Q8: B.8 | R8: B.8 | S8: R | T8: =_xlfn.LET( _xlpm.intervaloSoma, IF($S8="R", 'CEI_COMPLETA'!$E:$E, 'CEI_COMPLETA'!$D:$D), SUMIFS(_xlpm.intervaloSoma, 'CEI_COMPLETA'!$A:$A, Ajustes!T$1, 'CEI_COMPLETA'!$B:$B, Ajustes!$Q8) ) -> 107549 | U8: =_xlfn.LET( _xlpm.intervaloSoma, IF($S8="R", 'CEI_COMPLETA'!$E:$E, 'CEI_COMPLETA'!$D:$D), SUMIFS(_xlpm.intervaloSoma, 'CEI_COMPLETA'!$A:$A, Ajustes!U$1, 'CEI_COMPLETA'!$B:$B, Ajustes!$Q8) ) -> 116849 | V8: =_xlfn.LET( _xlpm.intervaloSoma, IF($S8="R", 'CEI_COMPLETA'!$E:$E, 'CEI_COMPLETA'!$D:$D), SUMIFS(_xlpm.intervaloSoma, 'CEI_COMPLETA'!$A:$A, Ajustes!V$1, 'CEI_COMPLETA'!$B:$B, Ajustes!$Q8) ) -> 136253 | W8: =_xlfn.LET( _xlpm.intervaloSoma, IF($S8="R", 'CEI_COMPLETA'!$E:$E, 'CEI_COMPLETA'!$D:$D), SUMIFS(_xlpm.intervaloSoma, 'CEI_COMPLETA'!$A:$A, Ajustes!W$1, 'CEI_COMPLETA'!$B:$B, Ajustes!$Q8) ) -> 148397 | X8: =_xlfn.LET( _xlpm.intervaloSoma, IF($S8="R", 'CEI_COMPLETA'!$E:$E, 'CEI_COMPLETA'!$D:$D), SUMIFS(_xlpm.intervaloSoma, 'CEI_COMPLETA'!$A:$A, Ajustes!X$1, 'CEI_COMPLETA'!$B:$B, Ajustes!$Q8) ) -> 161027 | Y8: =_xlfn.LET( _xlpm.intervaloSoma, IF($S8="R", 'CEI_COMPLETA'!$E:$E, 'CEI_COMPLETA'!$D:$D), SUMIFS(_xlpm.intervaloSoma, 'CEI_COMPLETA'!$A:$A, Ajustes!Y$1, 'CEI_COMPLETA'!$B:$B, Ajustes!$Q8) ) -> 163972 | Z8: =_xlfn.LET( _xlpm.intervaloSoma, IF($S8="R", 'CEI_COMPLETA'!$E:$E, 'CEI_COMPLETA'!$D:$D), SUMIFS(_xlpm.intervaloSoma, 'CEI_COMPLETA'!$A:$A, Ajustes!Z$1, 'CEI_COMPLETA'!$B:$B, Ajustes!$Q8) ) -> 175214 | AA8: =_xlfn.LET( _xlpm.intervaloSoma, IF($S8="R", 'CEI_COMPLETA'!$E:$E, 'CEI_COMPLETA'!$D:$D), SUMIFS(_xlpm.intervaloSoma, 'CEI_COMPLETA'!$A:$A, Ajustes!AA$1, 'CEI_COMPLETA'!$B:$B, Ajustes!$Q8) ) -> 189576 | ... AC8: =_xlfn.LET( _xlpm.intervaloSoma, IF($S8="R", 'CEI_COMPLETA'!$E:$E, 'CEI_COMPLETA'!$D:$D), SUMIFS(_xlpm.intervaloSoma, 'CEI_COMPLETA'!$A:$A, Ajustes!AC$1, 'CEI_COMPLETA'!$B:$B, Ajustes!$Q8) ) -> 231219 | AD8: =_xlfn.LET( _xlpm.intervaloSoma, IF($S8="R", 'CEI_COMPLETA'!$E:$E, 'CEI_COMPLETA'!$D:$D), SUMIFS(_xlpm.intervaloSoma, 'CEI_COMPLETA'!$A:$A, Ajustes!AD$1, 'CEI_COMPLETA'!$B:$B, Ajustes!$R8) ) -> 267784 | AE8: =_xlfn.LET( _xlpm.intervaloSoma, IF($S8="R", 'CEI_COMPLETA'!$E:$E, 'CEI_COMPLETA'!$D:$D), SUMIFS(_xlpm.intervaloSoma, 'CEI_COMPLETA'!$A:$A, Ajustes!AE$1, 'CEI_COMPLETA'!$B:$B, Ajustes!$R8) ) -> 296791 | AF8: =_xlfn.LET( _xlpm.intervaloSoma, IF($S8="R", 'CEI_COMPLETA'!$E:$E, 'CEI_COMPLETA'!$D:$D), SUMIFS(_xlpm.intervaloSoma, 'CEI_COMPLETA'!$A:$A, Ajustes!AF$1, 'CEI_COMPLETA'!$B:$B, Ajustes!$R8) ) -> 343646 | AG8: =_xlfn.LET( _xlpm.intervaloSoma, IF($S8="R", 'CEI_COMPLETA'!$E:$E, 'CEI_COMPLETA'!$D:$D), SUMIFS(_xlpm.intervaloSoma, 'CEI_COMPLETA'!$A:$A, Ajustes!AG$1, 'CEI_COMPLETA'!$B:$B, Ajustes!$R8) ) -> 385540 | AH8: =_xlfn.LET( _xlpm.intervaloSoma, IF($S8="R", 'CEI_COMPLETA'!$E:$E, 'CEI_COMPLETA'!$D:$D), SUMIFS(_xlpm.intervaloSoma, 'CEI_COMPLETA'!$A:$A, Ajustes!AH$1, 'CEI_COMPLETA'!$B:$B, Ajustes!$R8) ) -> 394290 | AI8: =_xlfn.LET( _xlpm.intervaloSoma, IF($S8="R", 'CEI_COMPLETA'!$E:$E, 'CEI_COMPLETA'!$D:$D), SUMIFS(_xlpm.intervaloSoma, 'CEI_COMPLETA'!$A:$A, Ajustes!AI$1, 'CEI_COMPLETA'!$B:$B, Ajustes!$R8) ) -> 493510 | AJ8: =_xlfn.LET( _xlpm.intervaloSoma, IF($S8="R", 'CEI_COMPLETA'!$E:$E, 'CEI_COMPLETA'!$D:$D), SUMIFS(_xlpm.intervaloSoma, 'CEI_COMPLETA'!$A:$A, Ajustes!AJ$1, 'CEI_COMPLETA'!$B:$B, Ajustes!$R8) ) -> 531088 | AK8: =_xlfn.LET( _xlpm.intervaloSoma, IF($S8="R", 'CEI_COMPLETA'!$E:$E, 'CEI_COMPLETA'!$D:$D), SUMIFS(_xlpm.intervaloSoma, 'CEI_COMPLETA'!$A:$A, Ajustes!AK$1, 'CEI_COMPLETA'!$B:$B, Ajustes!$R8) ) -> 563059 | ... AO8: =_xlfn.LET( _xlpm.intervaloSoma, IF($S8="R", 'CEI_COMPLETA'!$E:$E, 'CEI_COMPLETA'!$D:$D), SUMIFS(_xlpm.intervaloSoma, 'CEI_COMPLETA'!$A:$A, Ajustes!AO$1, 'CEI_COMPLETA'!$B:$B, Ajustes!$R8) ) -> 591302
A10: AJUSTES | T10: 2000 | U10: 2001 | V10: 2002 | W10: 2003 | X10: 2004 | Y10: 2005 | Z10: 2006 | AA10: 2007 | AB10: 2008 | AC10: 2009 | AD10: 2010 | AE10: 2011 | AF10: 2012 | AG10: 2013 | AH10: 2014 | AI10: 2015 | AJ10: 2016 | AK10: 2017 | AL10: 2018 | AM10: 2019 | AN10: 2020 | AO10: 2021
A11: Produção não-mercantil | I11: {=_xlfn.SWITCH(B11,0,0,"-",-1,"+",1)} -> 0 | J11: {=_xlfn.SWITCH(C11,0,0,"-",-1,"+",1)} -> 0 | K11: {=_xlfn.SWITCH(D11,0,0,"-",-1,"+",1)} -> 0 | L11: {=_xlfn.SWITCH(E11,0,0,"-",-1,"+",1)} -> 0 | M11: {=_xlfn.SWITCH(F11,0,0,"-",-1,"+",1)} -> 0 | N11: {=_xlfn.SWITCH(G11,0,0,"-",-1,"+",1)} -> 0 | O11: {=_xlfn.SWITCH(H11,0,0,"-",-1,"+",1)} -> 0 | T11: =SUM(T12:T14) -> 127301.62 | U11: =SUM(U12:U14) -> 131756.94 | V11: =SUM(V12:V14) -> 144068.99 | W11: =SUM(W12:W14) -> 156483.25 | X11: =SUM(X12:X14) -> 166144.09 | Y11: =SUM(Y12:Y14) -> 178614.98 | Z11: =SUM(Z12:Z14) -> 187466.72 | AA11: =SUM(AA12:AA14) -> 204036.25 | ... AO11: =SUM(AO12:AO14) -> 670410.08
A12: Aluguel Imputado | B12: - | C12: - | I12: {=_xlfn.SWITCH(B12,0,0,"-",-1,"+",1)} -> -1 | J12: {=_xlfn.SWITCH(C12,0,0,"-",-1,"+",1)} -> -1 | K12: {=_xlfn.SWITCH(D12,0,0,"-",-1,"+",1)} -> 0 | L12: {=_xlfn.SWITCH(E12,0,0,"-",-1,"+",1)} -> 0 | M12: {=_xlfn.SWITCH(F12,0,0,"-",-1,"+",1)} -> 0 | N12: {=_xlfn.SWITCH(G12,0,0,"-",-1,"+",1)} -> 0 | O12: {=_xlfn.SWITCH(H12,0,0,"-",-1,"+",1)} -> 0 | P12: TRU -Tabela 2 - Usos de bens e serviços - Descrição do Produto: Aluguel Imputado - aba demanda - coluna Consumo das Famílias | T12: 107290 | U12: 111313 | V12: 120331 | W12: 130517 | X12: 137783 | Y12: 149147 | Z12: 155582 | AA12: 168313 | AB12: 180243 | AC12: 199961 | AD12: 216622 | AE12: 249695 | AF12: 287350 | AG12: 335975 | AH12: 367290 | AI12: 400237 | AJ12: 423533 | AK12: 441426 | AL12: 460205 | AM12: 482425 | AN12: 516019 | AO12: 547406
A13: Autoconsumo (Agropecuária) | B13: - | C13: - | I13: {=_xlfn.SWITCH(B13,0,0,"-",-1,"+",1)} -> -1 | J13: {=_xlfn.SWITCH(C13,0,0,"-",-1,"+",1)} -> -1 | K13: {=_xlfn.SWITCH(D13,0,0,"-",-1,"+",1)} -> 0 | L13: {=_xlfn.SWITCH(E13,0,0,"-",-1,"+",1)} -> 0 | M13: {=_xlfn.SWITCH(F13,0,0,"-",-1,"+",1)} -> 0 | N13: {=_xlfn.SWITCH(G13,0,0,"-",-1,"+",1)} -> 0 | O13: {=_xlfn.SWITCH(H13,0,0,"-",-1,"+",1)} -> 0 | P13: POF + TRU | T13: 4490.548 | U13: 4922.3507 | V13: 5726.3239 | W13: 6488.0395 | X13: 6794.0781 | Y13: 7317.8925 | Z13: 8031.0548 | AA13: 8919.4675 | AB13: 10892.737 | AC13: 11473.96 | AD13: 12676.56 | AE13: 15237.845 | AF13: 16841.694 | AG13: 19470.841 | AH13: 20889.906 | AI13: 22640.026 | AJ13: 25501.369 | AK13: 25887.689 | AL13: 26236.004 | AM13: 28451.372 | AN13: 32732.573 | AO13: 39050.084
A14: Construção | B14: - | C14: - | I14: {=_xlfn.SWITCH(B14,0,0,"-",-1,"+",1)} -> -1 | J14: {=_xlfn.SWITCH(C14,0,0,"-",-1,"+",1)} -> -1 | K14: {=_xlfn.SWITCH(D14,0,0,"-",-1,"+",1)} -> 0 | L14: {=_xlfn.SWITCH(E14,0,0,"-",-1,"+",1)} -> 0 | M14: {=_xlfn.SWITCH(F14,0,0,"-",-1,"+",1)} -> 0 | N14: {=_xlfn.SWITCH(G14,0,0,"-",-1,"+",1)} -> 0 | O14: {=_xlfn.SWITCH(H14,0,0,"-",-1,"+",1)} -> 0 | P14: tab08, tab17, CEI | T14: 15521.071 | U14: 15521.589 | V14: 18011.669 | W14: 19478.213 | X14: 21567.01 | Y14: 22150.085 | Z14: 23853.668 | AA14: 26803.781 | AB14: 29797.2 | AC14: 36024.633 | AD14: 44349 | AE14: 48841 | AF14: 54094 | AG14: 58385 | AH14: 61187 | AI14: 63066 | AJ14: 63990 | AK14: 63806 | AL14: 68076 | AM14: 72340 | AN14: 76292 | AO14: 83954
A15: Investimento Residencial | I15: {=_xlfn.SWITCH(B15,0,0,"-",-1,"+",1)} -> 0 | J15: {=_xlfn.SWITCH(C15,0,0,"-",-1,"+",1)} -> 0 | K15: {=_xlfn.SWITCH(D15,0,0,"-",-1,"+",1)} -> 0 | L15: {=_xlfn.SWITCH(E15,0,0,"-",-1,"+",1)} -> 0 | M15: {=_xlfn.SWITCH(F15,0,0,"-",-1,"+",1)} -> 0 | N15: {=_xlfn.SWITCH(G15,0,0,"-",-1,"+",1)} -> 0 | O15: {=_xlfn.SWITCH(H15,0,0,"-",-1,"+",1)} -> 0 | T15: =T16 -> 66827.775 | U15: =U16 -> 66830.007 | V15: =V16 -> 77551.337 | W15: =W16 -> 83865.712 | X15: =X16 -> 92859.273 | Y15: =Y16 -> 95369.768 | Z15: =Z16 -> 102704.74 | AA15: =AA16 -> 115406.8 | ... AO15: =AO16 -> 376554.67
A16: Construção Residencial (total) | D16: - | E16: + | H16: - | I16: {=_xlfn.SWITCH(B16,0,0,"-",-1,"+",1)} -> 0 | J16: {=_xlfn.SWITCH(C16,0,0,"-",-1,"+",1)} -> 0 | K16: {=_xlfn.SWITCH(D16,0,0,"-",-1,"+",1)} -> -1 | L16: {=_xlfn.SWITCH(E16,0,0,"-",-1,"+",1)} -> 1 | M16: {=_xlfn.SWITCH(F16,0,0,"-",-1,"+",1)} -> 0 | N16: {=_xlfn.SWITCH(G16,0,0,"-",-1,"+",1)} -> 0 | O16: {=_xlfn.SWITCH(H16,0,0,"-",-1,"+",1)} -> -1 | P16: tab08, tab17, CEI | T16: 66827.775 | U16: 66830.007 | V16: 77551.337 | W16: 83865.712 | X16: 92859.273 | Y16: 95369.768 | Z16: 102704.74 | AA16: 115406.8 | AB16: 128295.31 | AC16: 155108.25 | AD16: 190949.78 | AE16: 220753.09 | AF16: 264764.19 | AG16: 300261.66 | AH16: 316290.69 | AI16: 324841.77 | AJ16: 316289.19 | AK16: 289667.52 | AL16: 293380.55 | AM16: 305428.36 | AN16: 318252.09 | AO16: 376554.67
A17: Construção Residencial (não-mercantil) | E17: - | I17: {=_xlfn.SWITCH(B17,0,0,"-",-1,"+",1)} -> 0 | J17: {=_xlfn.SWITCH(C17,0,0,"-",-1,"+",1)} -> 0 | K17: {=_xlfn.SWITCH(D17,0,0,"-",-1,"+",1)} -> 0 | L17: {=_xlfn.SWITCH(E17,0,0,"-",-1,"+",1)} -> -1 | M17: {=_xlfn.SWITCH(F17,0,0,"-",-1,"+",1)} -> 0 | N17: {=_xlfn.SWITCH(G17,0,0,"-",-1,"+",1)} -> 0 | O17: {=_xlfn.SWITCH(H17,0,0,"-",-1,"+",1)} -> 0 | P17: tab08, tab17, CEI | T17: 7482.7873 | U17: 7483.0372 | V17: 8683.5176 | W17: 9390.5459 | X17: 10397.566 | Y17: 10678.669 | Z17: 11499.975 | AA17: 12922.24 | AB17: 14365.382 | AC17: 17367.659 | AD17: 21380.879 | AE17: 23808.771 | AF17: 27712.932 | AG17: 31029.682 | AH17: 32588.778 | AI17: 36419.228 | AJ17: 39015.831 | AK17: 39156.484 | AL17: 42045.266 | AM17: 43819.625 | AN17: 43621.445 | AO17: 47315.41
A18: Renda de Propriedade sem acesso direto das famílias | B18: - | H18: - | I18: {=_xlfn.SWITCH(B18,0,0,"-",-1,"+",1)} -> -1 | J18: {=_xlfn.SWITCH(C18,0,0,"-",-1,"+",1)} -> 0 | K18: {=_xlfn.SWITCH(D18,0,0,"-",-1,"+",1)} -> 0 | L18: {=_xlfn.SWITCH(E18,0,0,"-",-1,"+",1)} -> 0 | M18: {=_xlfn.SWITCH(F18,0,0,"-",-1,"+",1)} -> 0 | N18: {=_xlfn.SWITCH(G18,0,0,"-",-1,"+",1)} -> 0 | O18: {=_xlfn.SWITCH(H18,0,0,"-",-1,"+",1)} -> -1 | P18: CEI | Q18: D.43-D.44 | R18: D.44 | S18: R | T18: =_xlfn.LET( _xlpm.intervaloSoma, IF($S18="R", 'CEI_COMPLETA'!$E:$E, 'CEI_COMPLETA'!$D:$D), SUMIFS(_xlpm.intervaloSoma, 'CEI_COMPLETA'!$A:$A, Ajustes!T$1, 'CEI_COMPLETA'!$B:$B, Ajustes!$Q18) ) -> 11331 | U18: =_xlfn.LET( _xlpm.intervaloSoma, IF($S18="R", 'CEI_COMPLETA'!$E:$E, 'CEI_COMPLETA'!$D:$D), SUMIFS(_xlpm.intervaloSoma, 'CEI_COMPLETA'!$A:$A, Ajustes!U$1, 'CEI_COMPLETA'!$B:$B, Ajustes!$Q18) ) -> 14687 | V18: =_xlfn.LET( _xlpm.intervaloSoma, IF($S18="R", 'CEI_COMPLETA'!$E:$E, 'CEI_COMPLETA'!$D:$D), SUMIFS(_xlpm.intervaloSoma, 'CEI_COMPLETA'!$A:$A, Ajustes!V$1, 'CEI_COMPLETA'!$B:$B, Ajustes!$Q18) ) -> 15190 | W18: =_xlfn.LET( _xlpm.intervaloSoma, IF($S18="R", 'CEI_COMPLETA'!$E:$E, 'CEI_COMPLETA'!$D:$D), SUMIFS(_xlpm.intervaloSoma, 'CEI_COMPLETA'!$A:$A, Ajustes!W$1, 'CEI_COMPLETA'!$B:$B, Ajustes!$Q18) ) -> 27074 | X18: =_xlfn.LET( _xlpm.intervaloSoma, IF($S18="R", 'CEI_COMPLETA'!$E:$E, 'CEI_COMPLETA'!$D:$D), SUMIFS(_xlpm.intervaloSoma, 'CEI_COMPLETA'!$A:$A, Ajustes!X$1, 'CEI_COMPLETA'!$B:$B, Ajustes!$Q18) ) -> 24602 | Y18: =_xlfn.LET( _xlpm.intervaloSoma, IF($S18="R", 'CEI_COMPLETA'!$E:$E, 'CEI_COMPLETA'!$D:$D), SUMIFS(_xlpm.intervaloSoma, 'CEI_COMPLETA'!$A:$A, Ajustes!Y$1, 'CEI_COMPLETA'!$B:$B, Ajustes!$Q18) ) -> 24607 | Z18: =_xlfn.LET( _xlpm.intervaloSoma, IF($S18="R", 'CEI_COMPLETA'!$E:$E, 'CEI_COMPLETA'!$D:$D), SUMIFS(_xlpm.intervaloSoma, 'CEI_COMPLETA'!$A:$A, Ajustes!Z$1, 'CEI_COMPLETA'!$B:$B, Ajustes!$Q18) ) -> 28239 | AA18: =_xlfn.LET( _xlpm.intervaloSoma, IF($S18="R", 'CEI_COMPLETA'!$E:$E, 'CEI_COMPLETA'!$D:$D), SUMIFS(_xlpm.intervaloSoma, 'CEI_COMPLETA'!$A:$A, Ajustes!AA$1, 'CEI_COMPLETA'!$B:$B, Ajustes!$Q18) ) -> 30586 | ... AC18: =_xlfn.LET( _xlpm.intervaloSoma, IF($S18="R", 'CEI_COMPLETA'!$E:$E, 'CEI_COMPLETA'!$D:$D), SUMIFS(_xlpm.intervaloSoma, 'CEI_COMPLETA'!$A:$A, Ajustes!AC$1, 'CEI_COMPLETA'!$B:$B, Ajustes!$Q18) ) -> 42827 | AD18: =_xlfn.LET( _xlpm.intervaloSoma, IF($S18="R", 'CEI_COMPLETA'!$E:$E, 'CEI_COMPLETA'!$D:$D), SUMIFS(_xlpm.intervaloSoma, 'CEI_COMPLETA'!$A:$A, Ajustes!AD$1, 'CEI_COMPLETA'!$B:$B, Ajustes!$R18) ) -> 60549 | AE18: =_xlfn.LET( _xlpm.intervaloSoma, IF($S18="R", 'CEI_COMPLETA'!$E:$E, 'CEI_COMPLETA'!$D:$D), SUMIFS(_xlpm.intervaloSoma, 'CEI_COMPLETA'!$A:$A, Ajustes!AE$1, 'CEI_COMPLETA'!$B:$B, Ajustes!$R18) ) -> 52629 | AF18: =_xlfn.LET( _xlpm.intervaloSoma, IF($S18="R", 'CEI_COMPLETA'!$E:$E, 'CEI_COMPLETA'!$D:$D), SUMIFS(_xlpm.intervaloSoma, 'CEI_COMPLETA'!$A:$A, Ajustes!AF$1, 'CEI_COMPLETA'!$B:$B, Ajustes!$R18) ) -> 80269 | AG18: =_xlfn.LET( _xlpm.intervaloSoma, IF($S18="R", 'CEI_COMPLETA'!$E:$E, 'CEI_COMPLETA'!$D:$D), SUMIFS(_xlpm.intervaloSoma, 'CEI_COMPLETA'!$A:$A, Ajustes!AG$1, 'CEI_COMPLETA'!$B:$B, Ajustes!$R18) ) -> 54208 | AH18: =_xlfn.LET( _xlpm.intervaloSoma, IF($S18="R", 'CEI_COMPLETA'!$E:$E, 'CEI_COMPLETA'!$D:$D), SUMIFS(_xlpm.intervaloSoma, 'CEI_COMPLETA'!$A:$A, Ajustes!AH$1, 'CEI_COMPLETA'!$B:$B, Ajustes!$R18) ) -> 58846 | AI18: =_xlfn.LET( _xlpm.intervaloSoma, IF($S18="R", 'CEI_COMPLETA'!$E:$E, 'CEI_COMPLETA'!$D:$D), SUMIFS(_xlpm.intervaloSoma, 'CEI_COMPLETA'!$A:$A, Ajustes!AI$1, 'CEI_COMPLETA'!$B:$B, Ajustes!$R18) ) -> 99434 | AJ18: =_xlfn.LET( _xlpm.intervaloSoma, IF($S18="R", 'CEI_COMPLETA'!$E:$E, 'CEI_COMPLETA'!$D:$D), SUMIFS(_xlpm.intervaloSoma, 'CEI_COMPLETA'!$A:$A, Ajustes!AJ$1, 'CEI_COMPLETA'!$B:$B, Ajustes!$R18) ) -> 87702 | AK18: =_xlfn.LET( _xlpm.intervaloSoma, IF($S18="R", 'CEI_COMPLETA'!$E:$E, 'CEI_COMPLETA'!$D:$D), SUMIFS(_xlpm.intervaloSoma, 'CEI_COMPLETA'!$A:$A, Ajustes!AK$1, 'CEI_COMPLETA'!$B:$B, Ajustes!$R18) ) -> 74085 | ... AO18: =_xlfn.LET( _xlpm.intervaloSoma, IF($S18="R", 'CEI_COMPLETA'!$E:$E, 'CEI_COMPLETA'!$D:$D), SUMIFS(_xlpm.intervaloSoma, 'CEI_COMPLETA'!$A:$A, Ajustes!AO$1, 'CEI_COMPLETA'!$B:$B, Ajustes!$R18) ) -> 81699
A19: Rendimento de investimentos atribuído a acionistas de fundos de investimento | I19: {=_xlfn.SWITCH(B19,0,0,"-",-1,"+",1)} -> 0 | J19: {=_xlfn.SWITCH(C19,0,0,"-",-1,"+",1)} -> 0 | K19: {=_xlfn.SWITCH(D19,0,0,"-",-1,"+",1)} -> 0 | L19: {=_xlfn.SWITCH(E19,0,0,"-",-1,"+",1)} -> 0 | M19: {=_xlfn.SWITCH(F19,0,0,"-",-1,"+",1)} -> 0 | N19: {=_xlfn.SWITCH(G19,0,0,"-",-1,"+",1)} -> 0 | O19: {=_xlfn.SWITCH(H19,0,0,"-",-1,"+",1)} -> 0 | P19: CEI | R19: D.443 | S19: R | T19: =_xlfn.LET( _xlpm.intervaloSoma, IF($S19="R", 'CEI_COMPLETA'!$E:$E, 'CEI_COMPLETA'!$D:$D), SUMIFS(_xlpm.intervaloSoma, 'CEI_COMPLETA'!$A:$A, Ajustes!T$1, 'CEI_COMPLETA'!$B:$B, Ajustes!$Q19) ) -> 0 | U19: =_xlfn.LET( _xlpm.intervaloSoma, IF($S19="R", 'CEI_COMPLETA'!$E:$E, 'CEI_COMPLETA'!$D:$D), SUMIFS(_xlpm.intervaloSoma, 'CEI_COMPLETA'!$A:$A, Ajustes!U$1, 'CEI_COMPLETA'!$B:$B, Ajustes!$Q19) ) -> 0 | V19: =_xlfn.LET( _xlpm.intervaloSoma, IF($S19="R", 'CEI_COMPLETA'!$E:$E, 'CEI_COMPLETA'!$D:$D), SUMIFS(_xlpm.intervaloSoma, 'CEI_COMPLETA'!$A:$A, Ajustes!V$1, 'CEI_COMPLETA'!$B:$B, Ajustes!$Q19) ) -> 0 | W19: =_xlfn.LET( _xlpm.intervaloSoma, IF($S19="R", 'CEI_COMPLETA'!$E:$E, 'CEI_COMPLETA'!$D:$D), SUMIFS(_xlpm.intervaloSoma, 'CEI_COMPLETA'!$A:$A, Ajustes!W$1, 'CEI_COMPLETA'!$B:$B, Ajustes!$Q19) ) -> 0 | X19: =_xlfn.LET( _xlpm.intervaloSoma, IF($S19="R", 'CEI_COMPLETA'!$E:$E, 'CEI_COMPLETA'!$D:$D), SUMIFS(_xlpm.intervaloSoma, 'CEI_COMPLETA'!$A:$A, Ajustes!X$1, 'CEI_COMPLETA'!$B:$B, Ajustes!$Q19) ) -> 0 | Y19: =_xlfn.LET( _xlpm.intervaloSoma, IF($S19="R", 'CEI_COMPLETA'!$E:$E, 'CEI_COMPLETA'!$D:$D), SUMIFS(_xlpm.intervaloSoma, 'CEI_COMPLETA'!$A:$A, Ajustes!Y$1, 'CEI_COMPLETA'!$B:$B, Ajustes!$Q19) ) -> 0 | Z19: =_xlfn.LET( _xlpm.intervaloSoma, IF($S19="R", 'CEI_COMPLETA'!$E:$E, 'CEI_COMPLETA'!$D:$D), SUMIFS(_xlpm.intervaloSoma, 'CEI_COMPLETA'!$A:$A, Ajustes!Z$1, 'CEI_COMPLETA'!$B:$B, Ajustes!$Q19) ) -> 0 | AA19: =_xlfn.LET( _xlpm.intervaloSoma, IF($S19="R", 'CEI_COMPLETA'!$E:$E, 'CEI_COMPLETA'!$D:$D), SUMIFS(_xlpm.intervaloSoma, 'CEI_COMPLETA'!$A:$A, Ajustes!AA$1, 'CEI_COMPLETA'!$B:$B, Ajustes!$Q19) ) -> 0 | ... AC19: =_xlfn.LET( _xlpm.intervaloSoma, IF($S19="R", 'CEI_COMPLETA'!$E:$E, 'CEI_COMPLETA'!$D:$D), SUMIFS(_xlpm.intervaloSoma, 'CEI_COMPLETA'!$A:$A, Ajustes!AC$1, 'CEI_COMPLETA'!$B:$B, Ajustes!$Q19) ) -> 0 | AD19: =_xlfn.LET( _xlpm.intervaloSoma, IF($S19="R", 'CEI_COMPLETA'!$E:$E, 'CEI_COMPLETA'!$D:$D), SUMIFS(_xlpm.intervaloSoma, 'CEI_COMPLETA'!$A:$A, Ajustes!AD$1, 'CEI_COMPLETA'!$B:$B, Ajustes!$R19) ) -> 7010 | AE19: =_xlfn.LET( _xlpm.intervaloSoma, IF($S19="R", 'CEI_COMPLETA'!$E:$E, 'CEI_COMPLETA'!$D:$D), SUMIFS(_xlpm.intervaloSoma, 'CEI_COMPLETA'!$A:$A, Ajustes!AE$1, 'CEI_COMPLETA'!$B:$B, Ajustes!$R19) ) -> 7694 | AF19: =_xlfn.LET( _xlpm.intervaloSoma, IF($S19="R", 'CEI_COMPLETA'!$E:$E, 'CEI_COMPLETA'!$D:$D), SUMIFS(_xlpm.intervaloSoma, 'CEI_COMPLETA'!$A:$A, Ajustes!AF$1, 'CEI_COMPLETA'!$B:$B, Ajustes!$R19) ) -> 12594 | AG19: =_xlfn.LET( _xlpm.intervaloSoma, IF($S19="R", 'CEI_COMPLETA'!$E:$E, 'CEI_COMPLETA'!$D:$D), SUMIFS(_xlpm.intervaloSoma, 'CEI_COMPLETA'!$A:$A, Ajustes!AG$1, 'CEI_COMPLETA'!$B:$B, Ajustes!$R19) ) -> 14142 | AH19: =_xlfn.LET( _xlpm.intervaloSoma, IF($S19="R", 'CEI_COMPLETA'!$E:$E, 'CEI_COMPLETA'!$D:$D), SUMIFS(_xlpm.intervaloSoma, 'CEI_COMPLETA'!$A:$A, Ajustes!AH$1, 'CEI_COMPLETA'!$B:$B, Ajustes!$R19) ) -> 12853 | AI19: =_xlfn.LET( _xlpm.intervaloSoma, IF($S19="R", 'CEI_COMPLETA'!$E:$E, 'CEI_COMPLETA'!$D:$D), SUMIFS(_xlpm.intervaloSoma, 'CEI_COMPLETA'!$A:$A, Ajustes!AI$1, 'CEI_COMPLETA'!$B:$B, Ajustes!$R19) ) -> 14074 | AJ19: =_xlfn.LET( _xlpm.intervaloSoma, IF($S19="R", 'CEI_COMPLETA'!$E:$E, 'CEI_COMPLETA'!$D:$D), SUMIFS(_xlpm.intervaloSoma, 'CEI_COMPLETA'!$A:$A, Ajustes!AJ$1, 'CEI_COMPLETA'!$B:$B, Ajustes!$R19) ) -> 16607 | AK19: =_xlfn.LET( _xlpm.intervaloSoma, IF($S19="R", 'CEI_COMPLETA'!$E:$E, 'CEI_COMPLETA'!$D:$D), SUMIFS(_xlpm.intervaloSoma, 'CEI_COMPLETA'!$A:$A, Ajustes!AK$1, 'CEI_COMPLETA'!$B:$B, Ajustes!$R19) ) -> 20365 | ... AO19: =_xlfn.LET( _xlpm.intervaloSoma, IF($S19="R", 'CEI_COMPLETA'!$E:$E, 'CEI_COMPLETA'!$D:$D), SUMIFS(_xlpm.intervaloSoma, 'CEI_COMPLETA'!$A:$A, Ajustes!AO$1, 'CEI_COMPLETA'!$B:$B, Ajustes!$R19) ) -> 7379
A20: Rendimento de investimentos atribuído a detentores de apólices de seguros | I20: {=_xlfn.SWITCH(B20,0,0,"-",-1,"+",1)} -> 0 | J20: {=_xlfn.SWITCH(C20,0,0,"-",-1,"+",1)} -> 0 | K20: {=_xlfn.SWITCH(D20,0,0,"-",-1,"+",1)} -> 0 | L20: {=_xlfn.SWITCH(E20,0,0,"-",-1,"+",1)} -> 0 | M20: {=_xlfn.SWITCH(F20,0,0,"-",-1,"+",1)} -> 0 | N20: {=_xlfn.SWITCH(G20,0,0,"-",-1,"+",1)} -> 0 | O20: {=_xlfn.SWITCH(H20,0,0,"-",-1,"+",1)} -> 0 | P20: CEI | R20: D.441 | S20: R | T20: =_xlfn.LET( _xlpm.intervaloSoma, IF($S20="R", 'CEI_COMPLETA'!$E:$E, 'CEI_COMPLETA'!$D:$D), SUMIFS(_xlpm.intervaloSoma, 'CEI_COMPLETA'!$A:$A, Ajustes!T$1, 'CEI_COMPLETA'!$B:$B, Ajustes!$Q20) ) -> 0 | U20: =_xlfn.LET( _xlpm.intervaloSoma, IF($S20="R", 'CEI_COMPLETA'!$E:$E, 'CEI_COMPLETA'!$D:$D), SUMIFS(_xlpm.intervaloSoma, 'CEI_COMPLETA'!$A:$A, Ajustes!U$1, 'CEI_COMPLETA'!$B:$B, Ajustes!$Q20) ) -> 0 | V20: =_xlfn.LET( _xlpm.intervaloSoma, IF($S20="R", 'CEI_COMPLETA'!$E:$E, 'CEI_COMPLETA'!$D:$D), SUMIFS(_xlpm.intervaloSoma, 'CEI_COMPLETA'!$A:$A, Ajustes!V$1, 'CEI_COMPLETA'!$B:$B, Ajustes!$Q20) ) -> 0 | W20: =_xlfn.LET( _xlpm.intervaloSoma, IF($S20="R", 'CEI_COMPLETA'!$E:$E, 'CEI_COMPLETA'!$D:$D), SUMIFS(_xlpm.intervaloSoma, 'CEI_COMPLETA'!$A:$A, Ajustes!W$1, 'CEI_COMPLETA'!$B:$B, Ajustes!$Q20) ) -> 0 | X20: =_xlfn.LET( _xlpm.intervaloSoma, IF($S20="R", 'CEI_COMPLETA'!$E:$E, 'CEI_COMPLETA'!$D:$D), SUMIFS(_xlpm.intervaloSoma, 'CEI_COMPLETA'!$A:$A, Ajustes!X$1, 'CEI_COMPLETA'!$B:$B, Ajustes!$Q20) ) -> 0 | Y20: =_xlfn.LET( _xlpm.intervaloSoma, IF($S20="R", 'CEI_COMPLETA'!$E:$E, 'CEI_COMPLETA'!$D:$D), SUMIFS(_xlpm.intervaloSoma, 'CEI_COMPLETA'!$A:$A, Ajustes!Y$1, 'CEI_COMPLETA'!$B:$B, Ajustes!$Q20) ) -> 0 | Z20: =_xlfn.LET( _xlpm.intervaloSoma, IF($S20="R", 'CEI_COMPLETA'!$E:$E, 'CEI_COMPLETA'!$D:$D), SUMIFS(_xlpm.intervaloSoma, 'CEI_COMPLETA'!$A:$A, Ajustes!Z$1, 'CEI_COMPLETA'!$B:$B, Ajustes!$Q20) ) -> 0 | AA20: =_xlfn.LET( _xlpm.intervaloSoma, IF($S20="R", 'CEI_COMPLETA'!$E:$E, 'CEI_COMPLETA'!$D:$D), SUMIFS(_xlpm.intervaloSoma, 'CEI_COMPLETA'!$A:$A, Ajustes!AA$1, 'CEI_COMPLETA'!$B:$B, Ajustes!$Q20) ) -> 0 | ... AC20: =_xlfn.LET( _xlpm.intervaloSoma, IF($S20="R", 'CEI_COMPLETA'!$E:$E, 'CEI_COMPLETA'!$D:$D), SUMIFS(_xlpm.intervaloSoma, 'CEI_COMPLETA'!$A:$A, Ajustes!AC$1, 'CEI_COMPLETA'!$B:$B, Ajustes!$Q20) ) -> 0 | AD20: =_xlfn.LET( _xlpm.intervaloSoma, IF($S20="R", 'CEI_COMPLETA'!$E:$E, 'CEI_COMPLETA'!$D:$D), SUMIFS(_xlpm.intervaloSoma, 'CEI_COMPLETA'!$A:$A, Ajustes!AD$1, 'CEI_COMPLETA'!$B:$B, Ajustes!$R20) ) -> 3863 | AE20: =_xlfn.LET( _xlpm.intervaloSoma, IF($S20="R", 'CEI_COMPLETA'!$E:$E, 'CEI_COMPLETA'!$D:$D), SUMIFS(_xlpm.intervaloSoma, 'CEI_COMPLETA'!$A:$A, Ajustes!AE$1, 'CEI_COMPLETA'!$B:$B, Ajustes!$R20) ) -> 4056 | AF20: =_xlfn.LET( _xlpm.intervaloSoma, IF($S20="R", 'CEI_COMPLETA'!$E:$E, 'CEI_COMPLETA'!$D:$D), SUMIFS(_xlpm.intervaloSoma, 'CEI_COMPLETA'!$A:$A, Ajustes!AF$1, 'CEI_COMPLETA'!$B:$B, Ajustes!$R20) ) -> 5027 | AG20: =_xlfn.LET( _xlpm.intervaloSoma, IF($S20="R", 'CEI_COMPLETA'!$E:$E, 'CEI_COMPLETA'!$D:$D), SUMIFS(_xlpm.intervaloSoma, 'CEI_COMPLETA'!$A:$A, Ajustes!AG$1, 'CEI_COMPLETA'!$B:$B, Ajustes!$R20) ) -> 3371 | AH20: =_xlfn.LET( _xlpm.intervaloSoma, IF($S20="R", 'CEI_COMPLETA'!$E:$E, 'CEI_COMPLETA'!$D:$D), SUMIFS(_xlpm.intervaloSoma, 'CEI_COMPLETA'!$A:$A, Ajustes!AH$1, 'CEI_COMPLETA'!$B:$B, Ajustes!$R20) ) -> 5386 | AI20: =_xlfn.LET( _xlpm.intervaloSoma, IF($S20="R", 'CEI_COMPLETA'!$E:$E, 'CEI_COMPLETA'!$D:$D), SUMIFS(_xlpm.intervaloSoma, 'CEI_COMPLETA'!$A:$A, Ajustes!AI$1, 'CEI_COMPLETA'!$B:$B, Ajustes!$R20) ) -> 5933 | AJ20: =_xlfn.LET( _xlpm.intervaloSoma, IF($S20="R", 'CEI_COMPLETA'!$E:$E, 'CEI_COMPLETA'!$D:$D), SUMIFS(_xlpm.intervaloSoma, 'CEI_COMPLETA'!$A:$A, Ajustes!AJ$1, 'CEI_COMPLETA'!$B:$B, Ajustes!$R20) ) -> 5988 | AK20: =_xlfn.LET( _xlpm.intervaloSoma, IF($S20="R", 'CEI_COMPLETA'!$E:$E, 'CEI_COMPLETA'!$D:$D), SUMIFS(_xlpm.intervaloSoma, 'CEI_COMPLETA'!$A:$A, Ajustes!AK$1, 'CEI_COMPLETA'!$B:$B, Ajustes!$R20) ) -> 5335 | ... AO20: =_xlfn.LET( _xlpm.intervaloSoma, IF($S20="R", 'CEI_COMPLETA'!$E:$E, 'CEI_COMPLETA'!$D:$D), SUMIFS(_xlpm.intervaloSoma, 'CEI_COMPLETA'!$A:$A, Ajustes!AO$1, 'CEI_COMPLETA'!$B:$B, Ajustes!$R20) ) -> 3891
A21: Rendimento de investimentos a pagar sobre direitos de pensão | I21: {=_xlfn.SWITCH(B21,0,0,"-",-1,"+",1)} -> 0 | J21: {=_xlfn.SWITCH(C21,0,0,"-",-1,"+",1)} -> 0 | K21: {=_xlfn.SWITCH(D21,0,0,"-",-1,"+",1)} -> 0 | L21: {=_xlfn.SWITCH(E21,0,0,"-",-1,"+",1)} -> 0 | M21: {=_xlfn.SWITCH(F21,0,0,"-",-1,"+",1)} -> 0 | N21: {=_xlfn.SWITCH(G21,0,0,"-",-1,"+",1)} -> 0 | O21: {=_xlfn.SWITCH(H21,0,0,"-",-1,"+",1)} -> 0 | P21: CEI | R21: D.442 | S21: R | T21: =_xlfn.LET( _xlpm.intervaloSoma, IF($S21="R", 'CEI_COMPLETA'!$E:$E, 'CEI_COMPLETA'!$D:$D), SUMIFS(_xlpm.intervaloSoma, 'CEI_COMPLETA'!$A:$A, Ajustes!T$1, 'CEI_COMPLETA'!$B:$B, Ajustes!$Q21) ) -> 0 | U21: =_xlfn.LET( _xlpm.intervaloSoma, IF($S21="R", 'CEI_COMPLETA'!$E:$E, 'CEI_COMPLETA'!$D:$D), SUMIFS(_xlpm.intervaloSoma, 'CEI_COMPLETA'!$A:$A, Ajustes!U$1, 'CEI_COMPLETA'!$B:$B, Ajustes!$Q21) ) -> 0 | V21: =_xlfn.LET( _xlpm.intervaloSoma, IF($S21="R", 'CEI_COMPLETA'!$E:$E, 'CEI_COMPLETA'!$D:$D), SUMIFS(_xlpm.intervaloSoma, 'CEI_COMPLETA'!$A:$A, Ajustes!V$1, 'CEI_COMPLETA'!$B:$B, Ajustes!$Q21) ) -> 0 | W21: =_xlfn.LET( _xlpm.intervaloSoma, IF($S21="R", 'CEI_COMPLETA'!$E:$E, 'CEI_COMPLETA'!$D:$D), SUMIFS(_xlpm.intervaloSoma, 'CEI_COMPLETA'!$A:$A, Ajustes!W$1, 'CEI_COMPLETA'!$B:$B, Ajustes!$Q21) ) -> 0 | X21: =_xlfn.LET( _xlpm.intervaloSoma, IF($S21="R", 'CEI_COMPLETA'!$E:$E, 'CEI_COMPLETA'!$D:$D), SUMIFS(_xlpm.intervaloSoma, 'CEI_COMPLETA'!$A:$A, Ajustes!X$1, 'CEI_COMPLETA'!$B:$B, Ajustes!$Q21) ) -> 0 | Y21: =_xlfn.LET( _xlpm.intervaloSoma, IF($S21="R", 'CEI_COMPLETA'!$E:$E, 'CEI_COMPLETA'!$D:$D), SUMIFS(_xlpm.intervaloSoma, 'CEI_COMPLETA'!$A:$A, Ajustes!Y$1, 'CEI_COMPLETA'!$B:$B, Ajustes!$Q21) ) -> 0 | Z21: =_xlfn.LET( _xlpm.intervaloSoma, IF($S21="R", 'CEI_COMPLETA'!$E:$E, 'CEI_COMPLETA'!$D:$D), SUMIFS(_xlpm.intervaloSoma, 'CEI_COMPLETA'!$A:$A, Ajustes!Z$1, 'CEI_COMPLETA'!$B:$B, Ajustes!$Q21) ) -> 0 | AA21: =_xlfn.LET( _xlpm.intervaloSoma, IF($S21="R", 'CEI_COMPLETA'!$E:$E, 'CEI_COMPLETA'!$D:$D), SUMIFS(_xlpm.intervaloSoma, 'CEI_COMPLETA'!$A:$A, Ajustes!AA$1, 'CEI_COMPLETA'!$B:$B, Ajustes!$Q21) ) -> 0 | ... AC21: =_xlfn.LET( _xlpm.intervaloSoma, IF($S21="R", 'CEI_COMPLETA'!$E:$E, 'CEI_COMPLETA'!$D:$D), SUMIFS(_xlpm.intervaloSoma, 'CEI_COMPLETA'!$A:$A, Ajustes!AC$1, 'CEI_COMPLETA'!$B:$B, Ajustes!$Q21) ) -> 0 | AD21: =_xlfn.LET( _xlpm.intervaloSoma, IF($S21="R", 'CEI_COMPLETA'!$E:$E, 'CEI_COMPLETA'!$D:$D), SUMIFS(_xlpm.intervaloSoma, 'CEI_COMPLETA'!$A:$A, Ajustes!AD$1, 'CEI_COMPLETA'!$B:$B, Ajustes!$R21) ) -> 49676 | AE21: =_xlfn.LET( _xlpm.intervaloSoma, IF($S21="R", 'CEI_COMPLETA'!$E:$E, 'CEI_COMPLETA'!$D:$D), SUMIFS(_xlpm.intervaloSoma, 'CEI_COMPLETA'!$A:$A, Ajustes!AE$1, 'CEI_COMPLETA'!$B:$B, Ajustes!$R21) ) -> 40879 | AF21: =_xlfn.LET( _xlpm.intervaloSoma, IF($S21="R", 'CEI_COMPLETA'!$E:$E, 'CEI_COMPLETA'!$D:$D), SUMIFS(_xlpm.intervaloSoma, 'CEI_COMPLETA'!$A:$A, Ajustes!AF$1, 'CEI_COMPLETA'!$B:$B, Ajustes!$R21) ) -> 62648 | AG21: =_xlfn.LET( _xlpm.intervaloSoma, IF($S21="R", 'CEI_COMPLETA'!$E:$E, 'CEI_COMPLETA'!$D:$D), SUMIFS(_xlpm.intervaloSoma, 'CEI_COMPLETA'!$A:$A, Ajustes!AG$1, 'CEI_COMPLETA'!$B:$B, Ajustes!$R21) ) -> 36695 | AH21: =_xlfn.LET( _xlpm.intervaloSoma, IF($S21="R", 'CEI_COMPLETA'!$E:$E, 'CEI_COMPLETA'!$D:$D), SUMIFS(_xlpm.intervaloSoma, 'CEI_COMPLETA'!$A:$A, Ajustes!AH$1, 'CEI_COMPLETA'!$B:$B, Ajustes!$R21) ) -> 40607 | AI21: =_xlfn.LET( _xlpm.intervaloSoma, IF($S21="R", 'CEI_COMPLETA'!$E:$E, 'CEI_COMPLETA'!$D:$D), SUMIFS(_xlpm.intervaloSoma, 'CEI_COMPLETA'!$A:$A, Ajustes!AI$1, 'CEI_COMPLETA'!$B:$B, Ajustes!$R21) ) -> 79427 | AJ21: =_xlfn.LET( _xlpm.intervaloSoma, IF($S21="R", 'CEI_COMPLETA'!$E:$E, 'CEI_COMPLETA'!$D:$D), SUMIFS(_xlpm.intervaloSoma, 'CEI_COMPLETA'!$A:$A, Ajustes!AJ$1, 'CEI_COMPLETA'!$B:$B, Ajustes!$R21) ) -> 65107 | AK21: =_xlfn.LET( _xlpm.intervaloSoma, IF($S21="R", 'CEI_COMPLETA'!$E:$E, 'CEI_COMPLETA'!$D:$D), SUMIFS(_xlpm.intervaloSoma, 'CEI_COMPLETA'!$A:$A, Ajustes!AK$1, 'CEI_COMPLETA'!$B:$B, Ajustes!$R21) ) -> 48385 | ... AO21: =_xlfn.LET( _xlpm.intervaloSoma, IF($S21="R", 'CEI_COMPLETA'!$E:$E, 'CEI_COMPLETA'!$D:$D), SUMIFS(_xlpm.intervaloSoma, 'CEI_COMPLETA'!$A:$A, Ajustes!AO$1, 'CEI_COMPLETA'!$B:$B, Ajustes!$R21) ) -> 70429
A22: Contribuições sociais dos empregadores (RECURSOS) | I22: {=_xlfn.SWITCH(B22,0,0,"-",-1,"+",1)} -> 0 | J22: {=_xlfn.SWITCH(C22,0,0,"-",-1,"+",1)} -> 0 | K22: {=_xlfn.SWITCH(D22,0,0,"-",-1,"+",1)} -> 0 | L22: {=_xlfn.SWITCH(E22,0,0,"-",-1,"+",1)} -> 0 | M22: {=_xlfn.SWITCH(F22,0,0,"-",-1,"+",1)} -> 0 | N22: {=_xlfn.SWITCH(G22,0,0,"-",-1,"+",1)} -> 0 | O22: {=_xlfn.SWITCH(H22,0,0,"-",-1,"+",1)} -> 0 | P22: CEI | Q22: D.12 | R22: D.12 | S22: R | T22: =_xlfn.LET( _xlpm.intervaloSoma, IF($S22="R", 'CEI_COMPLETA'!$E:$E, 'CEI_COMPLETA'!$D:$D), SUMIFS(_xlpm.intervaloSoma, 'CEI_COMPLETA'!$A:$A, Ajustes!T$1, 'CEI_COMPLETA'!$B:$B, Ajustes!$Q22) ) -> 89169 | U22: =_xlfn.LET( _xlpm.intervaloSoma, IF($S22="R", 'CEI_COMPLETA'!$E:$E, 'CEI_COMPLETA'!$D:$D), SUMIFS(_xlpm.intervaloSoma, 'CEI_COMPLETA'!$A:$A, Ajustes!U$1, 'CEI_COMPLETA'!$B:$B, Ajustes!$Q22) ) -> 102406 | V22: =_xlfn.LET( _xlpm.intervaloSoma, IF($S22="R", 'CEI_COMPLETA'!$E:$E, 'CEI_COMPLETA'!$D:$D), SUMIFS(_xlpm.intervaloSoma, 'CEI_COMPLETA'!$A:$A, Ajustes!V$1, 'CEI_COMPLETA'!$B:$B, Ajustes!$Q22) ) -> 112071 | W22: =_xlfn.LET( _xlpm.intervaloSoma, IF($S22="R", 'CEI_COMPLETA'!$E:$E, 'CEI_COMPLETA'!$D:$D), SUMIFS(_xlpm.intervaloSoma, 'CEI_COMPLETA'!$A:$A, Ajustes!W$1, 'CEI_COMPLETA'!$B:$B, Ajustes!$Q22) ) -> 130544 | X22: =_xlfn.LET( _xlpm.intervaloSoma, IF($S22="R", 'CEI_COMPLETA'!$E:$E, 'CEI_COMPLETA'!$D:$D), SUMIFS(_xlpm.intervaloSoma, 'CEI_COMPLETA'!$A:$A, Ajustes!X$1, 'CEI_COMPLETA'!$B:$B, Ajustes!$Q22) ) -> 150377 | Y22: =_xlfn.LET( _xlpm.intervaloSoma, IF($S22="R", 'CEI_COMPLETA'!$E:$E, 'CEI_COMPLETA'!$D:$D), SUMIFS(_xlpm.intervaloSoma, 'CEI_COMPLETA'!$A:$A, Ajustes!Y$1, 'CEI_COMPLETA'!$B:$B, Ajustes!$Q22) ) -> 167910 | Z22: =_xlfn.LET( _xlpm.intervaloSoma, IF($S22="R", 'CEI_COMPLETA'!$E:$E, 'CEI_COMPLETA'!$D:$D), SUMIFS(_xlpm.intervaloSoma, 'CEI_COMPLETA'!$A:$A, Ajustes!Z$1, 'CEI_COMPLETA'!$B:$B, Ajustes!$Q22) ) -> 186735 | AA22: =_xlfn.LET( _xlpm.intervaloSoma, IF($S22="R", 'CEI_COMPLETA'!$E:$E, 'CEI_COMPLETA'!$D:$D), SUMIFS(_xlpm.intervaloSoma, 'CEI_COMPLETA'!$A:$A, Ajustes!AA$1, 'CEI_COMPLETA'!$B:$B, Ajustes!$Q22) ) -> 217336 | ... AC22: =_xlfn.LET( _xlpm.intervaloSoma, IF($S22="R", 'CEI_COMPLETA'!$E:$E, 'CEI_COMPLETA'!$D:$D), SUMIFS(_xlpm.intervaloSoma, 'CEI_COMPLETA'!$A:$A, Ajustes!AC$1, 'CEI_COMPLETA'!$B:$B, Ajustes!$Q22) ) -> 286667 | AD22: =_xlfn.LET( _xlpm.intervaloSoma, IF($S22="R", 'CEI_COMPLETA'!$E:$E, 'CEI_COMPLETA'!$D:$D), SUMIFS(_xlpm.intervaloSoma, 'CEI_COMPLETA'!$A:$A, Ajustes!AD$1, 'CEI_COMPLETA'!$B:$B, Ajustes!$R22) ) -> 340905 | AE22: =_xlfn.LET( _xlpm.intervaloSoma, IF($S22="R", 'CEI_COMPLETA'!$E:$E, 'CEI_COMPLETA'!$D:$D), SUMIFS(_xlpm.intervaloSoma, 'CEI_COMPLETA'!$A:$A, Ajustes!AE$1, 'CEI_COMPLETA'!$B:$B, Ajustes!$R22) ) -> 393126 | AF22: =_xlfn.LET( _xlpm.intervaloSoma, IF($S22="R", 'CEI_COMPLETA'!$E:$E, 'CEI_COMPLETA'!$D:$D), SUMIFS(_xlpm.intervaloSoma, 'CEI_COMPLETA'!$A:$A, Ajustes!AF$1, 'CEI_COMPLETA'!$B:$B, Ajustes!$R22) ) -> 431871 | AG22: =_xlfn.LET( _xlpm.intervaloSoma, IF($S22="R", 'CEI_COMPLETA'!$E:$E, 'CEI_COMPLETA'!$D:$D), SUMIFS(_xlpm.intervaloSoma, 'CEI_COMPLETA'!$A:$A, Ajustes!AG$1, 'CEI_COMPLETA'!$B:$B, Ajustes!$R22) ) -> 483503 | AH22: =_xlfn.LET( _xlpm.intervaloSoma, IF($S22="R", 'CEI_COMPLETA'!$E:$E, 'CEI_COMPLETA'!$D:$D), SUMIFS(_xlpm.intervaloSoma, 'CEI_COMPLETA'!$A:$A, Ajustes!AH$1, 'CEI_COMPLETA'!$B:$B, Ajustes!$R22) ) -> 514960 | AI22: =_xlfn.LET( _xlpm.intervaloSoma, IF($S22="R", 'CEI_COMPLETA'!$E:$E, 'CEI_COMPLETA'!$D:$D), SUMIFS(_xlpm.intervaloSoma, 'CEI_COMPLETA'!$A:$A, Ajustes!AI$1, 'CEI_COMPLETA'!$B:$B, Ajustes!$R22) ) -> 545172 | AJ22: =_xlfn.LET( _xlpm.intervaloSoma, IF($S22="R", 'CEI_COMPLETA'!$E:$E, 'CEI_COMPLETA'!$D:$D), SUMIFS(_xlpm.intervaloSoma, 'CEI_COMPLETA'!$A:$A, Ajustes!AJ$1, 'CEI_COMPLETA'!$B:$B, Ajustes!$R22) ) -> 573144 | AK22: =_xlfn.LET( _xlpm.intervaloSoma, IF($S22="R", 'CEI_COMPLETA'!$E:$E, 'CEI_COMPLETA'!$D:$D), SUMIFS(_xlpm.intervaloSoma, 'CEI_COMPLETA'!$A:$A, Ajustes!AK$1, 'CEI_COMPLETA'!$B:$B, Ajustes!$R22) ) -> 608182 | ... AO22: =_xlfn.LET( _xlpm.intervaloSoma, IF($S22="R", 'CEI_COMPLETA'!$E:$E, 'CEI_COMPLETA'!$D:$D), SUMIFS(_xlpm.intervaloSoma, 'CEI_COMPLETA'!$A:$A, Ajustes!AO$1, 'CEI_COMPLETA'!$B:$B, Ajustes!$R22) ) -> 739634
A23: Contribuições sociais efetivas dos empregadores | I23: {=_xlfn.SWITCH(B23,0,0,"-",-1,"+",1)} -> 0 | J23: {=_xlfn.SWITCH(C23,0,0,"-",-1,"+",1)} -> 0 | K23: {=_xlfn.SWITCH(D23,0,0,"-",-1,"+",1)} -> 0 | L23: {=_xlfn.SWITCH(E23,0,0,"-",-1,"+",1)} -> 0 | M23: {=_xlfn.SWITCH(F23,0,0,"-",-1,"+",1)} -> 0 | N23: {=_xlfn.SWITCH(G23,0,0,"-",-1,"+",1)} -> 0 | O23: {=_xlfn.SWITCH(H23,0,0,"-",-1,"+",1)} -> 0 | P23: CEI | Q23: D.121 | R23: D.121 | S23: R | T23: =_xlfn.LET( _xlpm.intervaloSoma, IF($S23="R", 'CEI_COMPLETA'!$E:$E, 'CEI_COMPLETA'!$D:$D), SUMIFS(_xlpm.intervaloSoma, 'CEI_COMPLETA'!$A:$A, Ajustes!T$1, 'CEI_COMPLETA'!$B:$B, Ajustes!$Q23) ) -> 67435 | U23: =_xlfn.LET( _xlpm.intervaloSoma, IF($S23="R", 'CEI_COMPLETA'!$E:$E, 'CEI_COMPLETA'!$D:$D), SUMIFS(_xlpm.intervaloSoma, 'CEI_COMPLETA'!$A:$A, Ajustes!U$1, 'CEI_COMPLETA'!$B:$B, Ajustes!$Q23) ) -> 76664 | V23: =_xlfn.LET( _xlpm.intervaloSoma, IF($S23="R", 'CEI_COMPLETA'!$E:$E, 'CEI_COMPLETA'!$D:$D), SUMIFS(_xlpm.intervaloSoma, 'CEI_COMPLETA'!$A:$A, Ajustes!V$1, 'CEI_COMPLETA'!$B:$B, Ajustes!$Q23) ) -> 84063 | W23: =_xlfn.LET( _xlpm.intervaloSoma, IF($S23="R", 'CEI_COMPLETA'!$E:$E, 'CEI_COMPLETA'!$D:$D), SUMIFS(_xlpm.intervaloSoma, 'CEI_COMPLETA'!$A:$A, Ajustes!W$1, 'CEI_COMPLETA'!$B:$B, Ajustes!$Q23) ) -> 99492 | X23: =_xlfn.LET( _xlpm.intervaloSoma, IF($S23="R", 'CEI_COMPLETA'!$E:$E, 'CEI_COMPLETA'!$D:$D), SUMIFS(_xlpm.intervaloSoma, 'CEI_COMPLETA'!$A:$A, Ajustes!X$1, 'CEI_COMPLETA'!$B:$B, Ajustes!$Q23) ) -> 118417 | Y23: =_xlfn.LET( _xlpm.intervaloSoma, IF($S23="R", 'CEI_COMPLETA'!$E:$E, 'CEI_COMPLETA'!$D:$D), SUMIFS(_xlpm.intervaloSoma, 'CEI_COMPLETA'!$A:$A, Ajustes!Y$1, 'CEI_COMPLETA'!$B:$B, Ajustes!$Q23) ) -> 129466 | Z23: =_xlfn.LET( _xlpm.intervaloSoma, IF($S23="R", 'CEI_COMPLETA'!$E:$E, 'CEI_COMPLETA'!$D:$D), SUMIFS(_xlpm.intervaloSoma, 'CEI_COMPLETA'!$A:$A, Ajustes!Z$1, 'CEI_COMPLETA'!$B:$B, Ajustes!$Q23) ) -> 151749 | AA23: =_xlfn.LET( _xlpm.intervaloSoma, IF($S23="R", 'CEI_COMPLETA'!$E:$E, 'CEI_COMPLETA'!$D:$D), SUMIFS(_xlpm.intervaloSoma, 'CEI_COMPLETA'!$A:$A, Ajustes!AA$1, 'CEI_COMPLETA'!$B:$B, Ajustes!$Q23) ) -> 179752 | ... AC23: =_xlfn.LET( _xlpm.intervaloSoma, IF($S23="R", 'CEI_COMPLETA'!$E:$E, 'CEI_COMPLETA'!$D:$D), SUMIFS(_xlpm.intervaloSoma, 'CEI_COMPLETA'!$A:$A, Ajustes!AC$1, 'CEI_COMPLETA'!$B:$B, Ajustes!$Q23) ) -> 239770 | AD23: =_xlfn.LET( _xlpm.intervaloSoma, IF($S23="R", 'CEI_COMPLETA'!$E:$E, 'CEI_COMPLETA'!$D:$D), SUMIFS(_xlpm.intervaloSoma, 'CEI_COMPLETA'!$A:$A, Ajustes!AD$1, 'CEI_COMPLETA'!$B:$B, Ajustes!$R23) ) -> 290193 | AE23: =_xlfn.LET( _xlpm.intervaloSoma, IF($S23="R", 'CEI_COMPLETA'!$E:$E, 'CEI_COMPLETA'!$D:$D), SUMIFS(_xlpm.intervaloSoma, 'CEI_COMPLETA'!$A:$A, Ajustes!AE$1, 'CEI_COMPLETA'!$B:$B, Ajustes!$R23) ) -> 338487 | AF23: =_xlfn.LET( _xlpm.intervaloSoma, IF($S23="R", 'CEI_COMPLETA'!$E:$E, 'CEI_COMPLETA'!$D:$D), SUMIFS(_xlpm.intervaloSoma, 'CEI_COMPLETA'!$A:$A, Ajustes!AF$1, 'CEI_COMPLETA'!$B:$B, Ajustes!$R23) ) -> 374647 | AG23: =_xlfn.LET( _xlpm.intervaloSoma, IF($S23="R", 'CEI_COMPLETA'!$E:$E, 'CEI_COMPLETA'!$D:$D), SUMIFS(_xlpm.intervaloSoma, 'CEI_COMPLETA'!$A:$A, Ajustes!AG$1, 'CEI_COMPLETA'!$B:$B, Ajustes!$R23) ) -> 421108 | AH23: =_xlfn.LET( _xlpm.intervaloSoma, IF($S23="R", 'CEI_COMPLETA'!$E:$E, 'CEI_COMPLETA'!$D:$D), SUMIFS(_xlpm.intervaloSoma, 'CEI_COMPLETA'!$A:$A, Ajustes!AH$1, 'CEI_COMPLETA'!$B:$B, Ajustes!$R23) ) -> 445250 | AI23: =_xlfn.LET( _xlpm.intervaloSoma, IF($S23="R", 'CEI_COMPLETA'!$E:$E, 'CEI_COMPLETA'!$D:$D), SUMIFS(_xlpm.intervaloSoma, 'CEI_COMPLETA'!$A:$A, Ajustes!AI$1, 'CEI_COMPLETA'!$B:$B, Ajustes!$R23) ) -> 473185 | AJ23: =_xlfn.LET( _xlpm.intervaloSoma, IF($S23="R", 'CEI_COMPLETA'!$E:$E, 'CEI_COMPLETA'!$D:$D), SUMIFS(_xlpm.intervaloSoma, 'CEI_COMPLETA'!$A:$A, Ajustes!AJ$1, 'CEI_COMPLETA'!$B:$B, Ajustes!$R23) ) -> 494799 | AK23: =_xlfn.LET( _xlpm.intervaloSoma, IF($S23="R", 'CEI_COMPLETA'!$E:$E, 'CEI_COMPLETA'!$D:$D), SUMIFS(_xlpm.intervaloSoma, 'CEI_COMPLETA'!$A:$A, Ajustes!AK$1, 'CEI_COMPLETA'!$B:$B, Ajustes!$R23) ) -> 518850 | ... AO23: =_xlfn.LET( _xlpm.intervaloSoma, IF($S23="R", 'CEI_COMPLETA'!$E:$E, 'CEI_COMPLETA'!$D:$D), SUMIFS(_xlpm.intervaloSoma, 'CEI_COMPLETA'!$A:$A, Ajustes!AO$1, 'CEI_COMPLETA'!$B:$B, Ajustes!$R23) ) -> 639009
A24: Contribuições sociais imputadas dos empregadores | I24: {=_xlfn.SWITCH(B24,0,0,"-",-1,"+",1)} -> 0 | J24: {=_xlfn.SWITCH(C24,0,0,"-",-1,"+",1)} -> 0 | K24: {=_xlfn.SWITCH(D24,0,0,"-",-1,"+",1)} -> 0 | L24: {=_xlfn.SWITCH(E24,0,0,"-",-1,"+",1)} -> 0 | M24: {=_xlfn.SWITCH(F24,0,0,"-",-1,"+",1)} -> 0 | N24: {=_xlfn.SWITCH(G24,0,0,"-",-1,"+",1)} -> 0 | O24: {=_xlfn.SWITCH(H24,0,0,"-",-1,"+",1)} -> 0 | P24: CEI | Q24: D.122 | R24: D.122 | S24: R | T24: =_xlfn.LET( _xlpm.intervaloSoma, IF($S24="R", 'CEI_COMPLETA'!$E:$E, 'CEI_COMPLETA'!$D:$D), SUMIFS(_xlpm.intervaloSoma, 'CEI_COMPLETA'!$A:$A, Ajustes!T$1, 'CEI_COMPLETA'!$B:$B, Ajustes!$Q24) ) -> 21734 | U24: =_xlfn.LET( _xlpm.intervaloSoma, IF($S24="R", 'CEI_COMPLETA'!$E:$E, 'CEI_COMPLETA'!$D:$D), SUMIFS(_xlpm.intervaloSoma, 'CEI_COMPLETA'!$A:$A, Ajustes!U$1, 'CEI_COMPLETA'!$B:$B, Ajustes!$Q24) ) -> 25742 | V24: =_xlfn.LET( _xlpm.intervaloSoma, IF($S24="R", 'CEI_COMPLETA'!$E:$E, 'CEI_COMPLETA'!$D:$D), SUMIFS(_xlpm.intervaloSoma, 'CEI_COMPLETA'!$A:$A, Ajustes!V$1, 'CEI_COMPLETA'!$B:$B, Ajustes!$Q24) ) -> 28008 | W24: =_xlfn.LET( _xlpm.intervaloSoma, IF($S24="R", 'CEI_COMPLETA'!$E:$E, 'CEI_COMPLETA'!$D:$D), SUMIFS(_xlpm.intervaloSoma, 'CEI_COMPLETA'!$A:$A, Ajustes!W$1, 'CEI_COMPLETA'!$B:$B, Ajustes!$Q24) ) -> 31052 | X24: =_xlfn.LET( _xlpm.intervaloSoma, IF($S24="R", 'CEI_COMPLETA'!$E:$E, 'CEI_COMPLETA'!$D:$D), SUMIFS(_xlpm.intervaloSoma, 'CEI_COMPLETA'!$A:$A, Ajustes!X$1, 'CEI_COMPLETA'!$B:$B, Ajustes!$Q24) ) -> 31960 | Y24: =_xlfn.LET( _xlpm.intervaloSoma, IF($S24="R", 'CEI_COMPLETA'!$E:$E, 'CEI_COMPLETA'!$D:$D), SUMIFS(_xlpm.intervaloSoma, 'CEI_COMPLETA'!$A:$A, Ajustes!Y$1, 'CEI_COMPLETA'!$B:$B, Ajustes!$Q24) ) -> 38444 | Z24: =_xlfn.LET( _xlpm.intervaloSoma, IF($S24="R", 'CEI_COMPLETA'!$E:$E, 'CEI_COMPLETA'!$D:$D), SUMIFS(_xlpm.intervaloSoma, 'CEI_COMPLETA'!$A:$A, Ajustes!Z$1, 'CEI_COMPLETA'!$B:$B, Ajustes!$Q24) ) -> 34986 | AA24: =_xlfn.LET( _xlpm.intervaloSoma, IF($S24="R", 'CEI_COMPLETA'!$E:$E, 'CEI_COMPLETA'!$D:$D), SUMIFS(_xlpm.intervaloSoma, 'CEI_COMPLETA'!$A:$A, Ajustes!AA$1, 'CEI_COMPLETA'!$B:$B, Ajustes!$Q24) ) -> 37584 | ... AC24: =_xlfn.LET( _xlpm.intervaloSoma, IF($S24="R", 'CEI_COMPLETA'!$E:$E, 'CEI_COMPLETA'!$D:$D), SUMIFS(_xlpm.intervaloSoma, 'CEI_COMPLETA'!$A:$A, Ajustes!AC$1, 'CEI_COMPLETA'!$B:$B, Ajustes!$Q24) ) -> 46897 | AD24: =_xlfn.LET( _xlpm.intervaloSoma, IF($S24="R", 'CEI_COMPLETA'!$E:$E, 'CEI_COMPLETA'!$D:$D), SUMIFS(_xlpm.intervaloSoma, 'CEI_COMPLETA'!$A:$A, Ajustes!AD$1, 'CEI_COMPLETA'!$B:$B, Ajustes!$R24) ) -> 50712 | AE24: =_xlfn.LET( _xlpm.intervaloSoma, IF($S24="R", 'CEI_COMPLETA'!$E:$E, 'CEI_COMPLETA'!$D:$D), SUMIFS(_xlpm.intervaloSoma, 'CEI_COMPLETA'!$A:$A, Ajustes!AE$1, 'CEI_COMPLETA'!$B:$B, Ajustes!$R24) ) -> 54639 | AF24: =_xlfn.LET( _xlpm.intervaloSoma, IF($S24="R", 'CEI_COMPLETA'!$E:$E, 'CEI_COMPLETA'!$D:$D), SUMIFS(_xlpm.intervaloSoma, 'CEI_COMPLETA'!$A:$A, Ajustes!AF$1, 'CEI_COMPLETA'!$B:$B, Ajustes!$R24) ) -> 57224 | AG24: =_xlfn.LET( _xlpm.intervaloSoma, IF($S24="R", 'CEI_COMPLETA'!$E:$E, 'CEI_COMPLETA'!$D:$D), SUMIFS(_xlpm.intervaloSoma, 'CEI_COMPLETA'!$A:$A, Ajustes!AG$1, 'CEI_COMPLETA'!$B:$B, Ajustes!$R24) ) -> 62395 | AH24: =_xlfn.LET( _xlpm.intervaloSoma, IF($S24="R", 'CEI_COMPLETA'!$E:$E, 'CEI_COMPLETA'!$D:$D), SUMIFS(_xlpm.intervaloSoma, 'CEI_COMPLETA'!$A:$A, Ajustes!AH$1, 'CEI_COMPLETA'!$B:$B, Ajustes!$R24) ) -> 69710 | AI24: =_xlfn.LET( _xlpm.intervaloSoma, IF($S24="R", 'CEI_COMPLETA'!$E:$E, 'CEI_COMPLETA'!$D:$D), SUMIFS(_xlpm.intervaloSoma, 'CEI_COMPLETA'!$A:$A, Ajustes!AI$1, 'CEI_COMPLETA'!$B:$B, Ajustes!$R24) ) -> 71987 | AJ24: =_xlfn.LET( _xlpm.intervaloSoma, IF($S24="R", 'CEI_COMPLETA'!$E:$E, 'CEI_COMPLETA'!$D:$D), SUMIFS(_xlpm.intervaloSoma, 'CEI_COMPLETA'!$A:$A, Ajustes!AJ$1, 'CEI_COMPLETA'!$B:$B, Ajustes!$R24) ) -> 78345 | AK24: =_xlfn.LET( _xlpm.intervaloSoma, IF($S24="R", 'CEI_COMPLETA'!$E:$E, 'CEI_COMPLETA'!$D:$D), SUMIFS(_xlpm.intervaloSoma, 'CEI_COMPLETA'!$A:$A, Ajustes!AK$1, 'CEI_COMPLETA'!$B:$B, Ajustes!$R24) ) -> 89332 | ... AO24: =_xlfn.LET( _xlpm.intervaloSoma, IF($S24="R", 'CEI_COMPLETA'!$E:$E, 'CEI_COMPLETA'!$D:$D), SUMIFS(_xlpm.intervaloSoma, 'CEI_COMPLETA'!$A:$A, Ajustes!AO$1, 'CEI_COMPLETA'!$B:$B, Ajustes!$R24) ) -> 100625
A25: Contribuições sociais (USOS) | I25: {=_xlfn.SWITCH(B25,0,0,"-",-1,"+",1)} -> 0 | J25: {=_xlfn.SWITCH(C25,0,0,"-",-1,"+",1)} -> 0 | K25: {=_xlfn.SWITCH(D25,0,0,"-",-1,"+",1)} -> 0 | L25: {=_xlfn.SWITCH(E25,0,0,"-",-1,"+",1)} -> 0 | M25: {=_xlfn.SWITCH(F25,0,0,"-",-1,"+",1)} -> 0 | N25: {=_xlfn.SWITCH(G25,0,0,"-",-1,"+",1)} -> 0 | O25: {=_xlfn.SWITCH(H25,0,0,"-",-1,"+",1)} -> 0 | P25: CEI | Q25: D.61 | R25: D.61 | S25: U | T25: =_xlfn.LET( _xlpm.intervaloSoma, IF($S25="R", 'CEI_COMPLETA'!$E:$E, 'CEI_COMPLETA'!$D:$D), SUMIFS(_xlpm.intervaloSoma, 'CEI_COMPLETA'!$A:$A, Ajustes!T$1, 'CEI_COMPLETA'!$B:$B, Ajustes!$Q25) ) -> 129632 | U25: =_xlfn.LET( _xlpm.intervaloSoma, IF($S25="R", 'CEI_COMPLETA'!$E:$E, 'CEI_COMPLETA'!$D:$D), SUMIFS(_xlpm.intervaloSoma, 'CEI_COMPLETA'!$A:$A, Ajustes!U$1, 'CEI_COMPLETA'!$B:$B, Ajustes!$Q25) ) -> 151615 | V25: =_xlfn.LET( _xlpm.intervaloSoma, IF($S25="R", 'CEI_COMPLETA'!$E:$E, 'CEI_COMPLETA'!$D:$D), SUMIFS(_xlpm.intervaloSoma, 'CEI_COMPLETA'!$A:$A, Ajustes!V$1, 'CEI_COMPLETA'!$B:$B, Ajustes!$Q25) ) -> 170707 | W25: =_xlfn.LET( _xlpm.intervaloSoma, IF($S25="R", 'CEI_COMPLETA'!$E:$E, 'CEI_COMPLETA'!$D:$D), SUMIFS(_xlpm.intervaloSoma, 'CEI_COMPLETA'!$A:$A, Ajustes!W$1, 'CEI_COMPLETA'!$B:$B, Ajustes!$Q25) ) -> 194502 | X25: =_xlfn.LET( _xlpm.intervaloSoma, IF($S25="R", 'CEI_COMPLETA'!$E:$E, 'CEI_COMPLETA'!$D:$D), SUMIFS(_xlpm.intervaloSoma, 'CEI_COMPLETA'!$A:$A, Ajustes!X$1, 'CEI_COMPLETA'!$B:$B, Ajustes!$Q25) ) -> 215107 | Y25: =_xlfn.LET( _xlpm.intervaloSoma, IF($S25="R", 'CEI_COMPLETA'!$E:$E, 'CEI_COMPLETA'!$D:$D), SUMIFS(_xlpm.intervaloSoma, 'CEI_COMPLETA'!$A:$A, Ajustes!Y$1, 'CEI_COMPLETA'!$B:$B, Ajustes!$Q25) ) -> 247112 | Z25: =_xlfn.LET( _xlpm.intervaloSoma, IF($S25="R", 'CEI_COMPLETA'!$E:$E, 'CEI_COMPLETA'!$D:$D), SUMIFS(_xlpm.intervaloSoma, 'CEI_COMPLETA'!$A:$A, Ajustes!Z$1, 'CEI_COMPLETA'!$B:$B, Ajustes!$Q25) ) -> 282410 | AA25: =_xlfn.LET( _xlpm.intervaloSoma, IF($S25="R", 'CEI_COMPLETA'!$E:$E, 'CEI_COMPLETA'!$D:$D), SUMIFS(_xlpm.intervaloSoma, 'CEI_COMPLETA'!$A:$A, Ajustes!AA$1, 'CEI_COMPLETA'!$B:$B, Ajustes!$Q25) ) -> 315996 | ... AC25: =_xlfn.LET( _xlpm.intervaloSoma, IF($S25="R", 'CEI_COMPLETA'!$E:$E, 'CEI_COMPLETA'!$D:$D), SUMIFS(_xlpm.intervaloSoma, 'CEI_COMPLETA'!$A:$A, Ajustes!AC$1, 'CEI_COMPLETA'!$B:$B, Ajustes!$Q25) ) -> 393773 | AD25: =_xlfn.LET( _xlpm.intervaloSoma, IF($S25="R", 'CEI_COMPLETA'!$E:$E, 'CEI_COMPLETA'!$D:$D), SUMIFS(_xlpm.intervaloSoma, 'CEI_COMPLETA'!$A:$A, Ajustes!AD$1, 'CEI_COMPLETA'!$B:$B, Ajustes!$R25) ) -> 474322 | AE25: =_xlfn.LET( _xlpm.intervaloSoma, IF($S25="R", 'CEI_COMPLETA'!$E:$E, 'CEI_COMPLETA'!$D:$D), SUMIFS(_xlpm.intervaloSoma, 'CEI_COMPLETA'!$A:$A, Ajustes!AE$1, 'CEI_COMPLETA'!$B:$B, Ajustes!$R25) ) -> 529663 | AF25: =_xlfn.LET( _xlpm.intervaloSoma, IF($S25="R", 'CEI_COMPLETA'!$E:$E, 'CEI_COMPLETA'!$D:$D), SUMIFS(_xlpm.intervaloSoma, 'CEI_COMPLETA'!$A:$A, Ajustes!AF$1, 'CEI_COMPLETA'!$B:$B, Ajustes!$R25) ) -> 599944 | AG25: =_xlfn.LET( _xlpm.intervaloSoma, IF($S25="R", 'CEI_COMPLETA'!$E:$E, 'CEI_COMPLETA'!$D:$D), SUMIFS(_xlpm.intervaloSoma, 'CEI_COMPLETA'!$A:$A, Ajustes!AG$1, 'CEI_COMPLETA'!$B:$B, Ajustes!$R25) ) -> 641336 | AH25: =_xlfn.LET( _xlpm.intervaloSoma, IF($S25="R", 'CEI_COMPLETA'!$E:$E, 'CEI_COMPLETA'!$D:$D), SUMIFS(_xlpm.intervaloSoma, 'CEI_COMPLETA'!$A:$A, Ajustes!AH$1, 'CEI_COMPLETA'!$B:$B, Ajustes!$R25) ) -> 690113 | AI25: =_xlfn.LET( _xlpm.intervaloSoma, IF($S25="R", 'CEI_COMPLETA'!$E:$E, 'CEI_COMPLETA'!$D:$D), SUMIFS(_xlpm.intervaloSoma, 'CEI_COMPLETA'!$A:$A, Ajustes!AI$1, 'CEI_COMPLETA'!$B:$B, Ajustes!$R25) ) -> 768026 | AJ25: =_xlfn.LET( _xlpm.intervaloSoma, IF($S25="R", 'CEI_COMPLETA'!$E:$E, 'CEI_COMPLETA'!$D:$D), SUMIFS(_xlpm.intervaloSoma, 'CEI_COMPLETA'!$A:$A, Ajustes!AJ$1, 'CEI_COMPLETA'!$B:$B, Ajustes!$R25) ) -> 787092 | AK25: =_xlfn.LET( _xlpm.intervaloSoma, IF($S25="R", 'CEI_COMPLETA'!$E:$E, 'CEI_COMPLETA'!$D:$D), SUMIFS(_xlpm.intervaloSoma, 'CEI_COMPLETA'!$A:$A, Ajustes!AK$1, 'CEI_COMPLETA'!$B:$B, Ajustes!$R25) ) -> 807880 | ... AO25: =_xlfn.LET( _xlpm.intervaloSoma, IF($S25="R", 'CEI_COMPLETA'!$E:$E, 'CEI_COMPLETA'!$D:$D), SUMIFS(_xlpm.intervaloSoma, 'CEI_COMPLETA'!$A:$A, Ajustes!AO$1, 'CEI_COMPLETA'!$B:$B, Ajustes!$R25) ) -> 1013186
